File: data/b.csv
Time (s);Position (mm);Force (kN);Strain (%);
"0.0000";"0.0000";"0.0010";"-0.0001"
"0.2500";"0.0024";"0.0115";"-0.0003"
"0.5000";"0.0083";"0.0256";"-0.0001"
"0.7500";"0.0124";"0.0304";"-0.0001"
"1.0000";"0.0165";"0.0354";"-0.0003"
"1.2500";"0.0208";"0.0401";"-0.0001"
"1.5000";"0.0251";"0.0458";"-0.0001"
"1.7500";"0.0292";"0.0500";"-0.0005"
"2.0000";"0.0332";"0.0537";"-0.0004"
"2.2500";"0.0373";"0.0581";"-0.0004"
"2.5000";"0.0416";"0.0614";"-0.0004"
"2.7500";"0.0460";"0.0666";"-0.0007"
"3.0000";"0.0501";"0.0695";"-0.0009"
"3.2500";"0.0541";"0.0744";"-0.0008"
"3.5000";"0.0582";"0.0799";"-0.0011"
"3.7500";"0.0623";"0.0859";"-0.0012"
"4.0000";"0.0667";"0.0914";"-0.0013"
"4.2500";"0.0710";"0.0969";"-0.0013"
"4.5000";"0.0751";"0.1025";"-0.0014"
"4.7500";"0.0791";"0.1085";"-0.0017"
"5.0000";"0.0832";"0.1158";"-0.0017"
"5.2500";"0.0875";"0.1268";"-0.0016"
"5.5000";"0.0918";"0.1409";"-0.0019"
"5.7500";"0.0959";"0.1584";"-0.0021"
"6.0000";"0.1000";"0.1739";"-0.0019"
"6.2500";"0.1040";"0.1882";"-0.0016"
"6.5000";"0.1083";"0.2026";"-0.0017"
"6.7500";"0.1126";"0.2181";"-0.0019"
"7.0000";"0.1168";"0.2323";"-0.0021"
"7.2500";"0.1208";"0.2460";"-0.0019"
"7.5000";"0.1249";"0.2598";"-0.0018"
"7.7500";"0.1290";"0.2715";"-0.0022"
"8.0000";"0.1334";"0.2860";"-0.0016"
"8.2500";"0.1377";"0.2982";"-0.0021"
"8.5000";"0.1418";"0.3102";"-0.0022"
"8.7500";"0.1457";"0.3201";"-0.0016"
"9.0000";"0.1498";"0.3302";"-0.0019"
"9.2500";"0.1540";"0.3414";"-0.0023"
"9.5000";"0.1584";"0.3523";"-0.0017"
"9.7500";"0.1626";"0.3635";"-0.0018"
"10.0000";"0.1667";"0.3726";"-0.0025"
"10.2500";"0.1707";"0.3817";"-0.0017"
"10.5000";"0.1748";"0.3911";"-0.0020"
"10.7500";"0.1792";"0.4010";"-0.0023"
"11.0000";"0.1834";"0.4114";"-0.0021"
"11.2500";"0.1875";"0.4195";"-0.0020"
"11.5000";"0.1915";"0.4278";"-0.0023"
"11.7500";"0.1957";"0.4361";"-0.0024"
"12.0000";"0.2000";"0.4460";"-0.0021"
"12.2500";"0.2044";"0.4565";"-0.0025"
"12.5000";"0.2084";"0.4643";"-0.0024"
"12.7500";"0.2124";"0.4726";"-0.0025"
"13.0000";"0.2165";"0.4801";"-0.0024"
"13.2500";"0.2208";"0.4902";"-0.0025"
"13.5000";"0.2251";"0.5015";"-0.0025"
"13.7500";"0.2293";"0.5106";"-0.0027"
"14.0000";"0.2334";"0.5191";"-0.0026"
"14.2500";"0.2373";"0.5261";"-0.0028"
"14.5000";"0.2415";"0.5354";"-0.0027"
"14.7500";"0.2458";"0.5464";"-0.0027"
"15.0000";"0.2501";"0.5583";"-0.0028"
"15.2500";"0.2542";"0.5685";"-0.0028"
"15.5000";"0.2582";"0.5770";"-0.0028"
"15.7500";"0.2624";"0.5873";"-0.0030"
"16.0000";"0.2667";"0.5981";"-0.0029"
"16.2500";"0.2710";"0.6114";"-0.0026"
"16.5000";"0.2750";"0.6231";"-0.0029"
"16.7500";"0.2791";"0.6327";"-0.0029"
"17.0000";"0.2832";"0.6429";"-0.0027"
"17.2500";"0.2874";"0.6538";"-0.0027"
"17.5000";"0.2918";"0.6696";"-0.0026"
"17.7500";"0.2960";"0.6823";"-0.0025"
"18.0000";"0.3000";"0.6925";"-0.0025"
"18.2500";"0.3040";"0.7028";"-0.0024"
"18.5000";"0.3081";"0.7129";"-0.0022"
"18.7500";"0.3125";"0.7276";"-0.0024"
"19.0000";"0.3168";"0.7426";"-0.0020"
"19.2500";"0.3209";"0.7552";"-0.0020"
"19.5000";"0.3250";"0.7659";"-0.0020"
"19.7500";"0.3291";"0.7761";"-0.0017"
"20.0000";"0.3333";"0.7899";"-0.0017"
"20.2500";"0.3376";"0.8063";"-0.0016"
"20.5000";"0.3417";"0.8215";"-0.0011"
"20.7500";"0.3458";"0.8338";"-0.0011"
"21.0000";"0.3499";"0.8457";"-0.0010"
"21.2500";"0.3541";"0.8596";"-0.0011"
"21.5000";"0.3584";"0.8761";"-0.0005"
"21.7500";"0.3626";"0.8939";"-0.0007"
"22.0000";"0.3666";"0.9077";"-0.0006"
"22.2500";"0.3707";"0.9183";"-0.0003"
"22.5000";"0.3748";"0.9316";"0.0001"
"22.7500";"0.3792";"0.9473";"0.0001"
"23.0000";"0.3835";"0.9667";"0.0004"
"23.2500";"0.3876";"0.9834";"0.0004"
"23.5000";"0.3916";"0.9968";"0.0007"
"23.7500";"0.3957";"1.0110";"0.0008"
"24.0000";"0.3999";"1.0264";"0.0011"
"24.2500";"0.4043";"1.0490";"0.0013"
"24.5000";"0.4084";"1.0656";"0.0015"
"24.7500";"0.4125";"1.0790";"0.0016"
"25.0000";"0.4165";"1.0913";"0.0018"
"25.2500";"0.4208";"1.1060";"0.0021"
"25.5000";"0.4251";"1.1257";"0.0024"
"25.7500";"0.4293";"1.1442";"0.0024"
"26.0000";"0.4333";"1.1585";"0.0026"
"26.2500";"0.4373";"1.1711";"0.0029"
"26.5000";"0.4416";"1.1852";"0.0031"
"26.7500";"0.4459";"1.2040";"0.0032"
"27.0000";"0.4502";"1.2241";"0.0036"
"27.2500";"0.4542";"1.2390";"0.0038"
"27.5000";"0.4583";"1.2513";"0.0038"
"27.7500";"0.4623";"1.2638";"0.0040"
"28.0000";"0.4666";"1.2810";"0.0045"
"28.2500";"0.4709";"1.2998";"0.0043"
"28.5000";"0.4751";"1.3193";"0.0046"
"28.7500";"0.4792";"1.3323";"0.0051"
"29.0000";"0.4832";"1.3437";"0.0050"
"29.2500";"0.4874";"1.3594";"0.0047"
"29.5000";"0.4917";"1.3774";"0.0054"
"29.7500";"0.4959";"1.3985";"0.0058"
"30.0000";"0.5000";"1.4134";"0.0056"
"30.2500";"0.5041";"1.4263";"0.0058"
"30.5000";"0.5082";"1.4391";"0.0061"
"30.7500";"0.5125";"1.4568";"0.0063"
"31.0000";"0.5168";"1.4769";"0.0064"
"31.2500";"0.5209";"1.4944";"0.0068"
"31.5000";"0.5249";"1.5068";"0.0067"
"31.7500";"0.5290";"1.5208";"0.0068"
"32.0000";"0.5332";"1.5366";"0.0072"
"32.2500";"0.5376";"1.5576";"0.0076"
"32.5000";"0.5419";"1.5767";"0.0075"
"32.7500";"0.5458";"1.5895";"0.0077"
"33.0000";"0.5499";"1.6025";"0.0080"
"33.2500";"0.5540";"1.6155";"0.0080"
"33.5000";"0.5583";"1.6354";"0.0083"
"33.7500";"0.5626";"1.6571";"0.0084"
"34.0000";"0.5668";"1.6737";"0.0086"
"34.2500";"0.5708";"1.6857";"0.0090"
"34.5000";"0.5748";"1.6989";"0.0086"
"34.7500";"0.5791";"1.7171";"0.0091"
"35.0000";"0.5835";"1.7392";"0.0097"
"35.2500";"0.5876";"1.7568";"0.0096"
"35.5000";"0.5916";"1.7709";"0.0094"
"35.7500";"0.5957";"1.7833";"0.0101"
"36.0000";"0.5999";"1.8004";"0.0104"
"36.2500";"0.6044";"1.8220";"0.0099"
"36.5000";"0.6085";"1.8421";"0.0103"
"36.7500";"0.6125";"1.8558";"0.0111"
"37.0000";"0.6165";"1.8677";"0.0106"
"37.2500";"0.6206";"1.8831";"0.0105"
"37.5000";"0.6250";"1.9035";"0.0114"
"37.7500";"0.6293";"1.9255";"0.0115"
"38.0000";"0.6334";"1.9424";"0.0111"
"38.2500";"0.6374";"1.9544";"0.0117"
"38.5000";"0.6415";"1.9686";"0.0123"
"38.7500";"0.6458";"1.9868";"0.0119"
"39.0000";"0.6501";"2.0073";"0.0119"
"39.2500";"0.6542";"2.0276";"0.0127"
"39.5000";"0.6583";"2.0412";"0.0128"
"39.7500";"0.6624";"2.0559";"0.0126"
"40.0000";"0.6666";"2.0727";"0.0131"
"40.2500";"0.6709";"2.0920";"0.0130"
"40.5000";"0.6751";"2.1139";"0.0133"
"40.7500";"0.6791";"2.1295";"0.0135"
"41.0000";"0.6832";"2.1446";"0.0137"
"41.2500";"0.6873";"2.1597";"0.0139"
"41.5000";"0.6917";"2.1787";"0.0139"
"41.7500";"0.6960";"2.2014";"0.0144"
"42.0000";"0.7001";"2.2193";"0.0147"
"42.2500";"0.7041";"2.2327";"0.0145"
"42.5000";"0.7082";"2.2475";"0.0148"
"42.7500";"0.7124";"2.2637";"0.0150"
"43.0000";"0.7168";"2.2874";"0.0153"
"43.2500";"0.7209";"2.3079";"0.0155"
"43.5000";"0.7250";"2.3231";"0.0155"
"43.7500";"0.7291";"2.3370";"0.0154"
"44.0000";"0.7332";"2.3524";"0.0161"
"44.2500";"0.7375";"2.3730";"0.0161"
"44.5000";"0.7418";"2.3956";"0.0161"
"44.7500";"0.7459";"2.4135";"0.0166"
"45.0000";"0.7499";"2.4278";"0.0169"
"45.2500";"0.7541";"2.4425";"0.0167"
"45.5000";"0.7584";"2.4616";"0.0171"
"45.7500";"0.7627";"2.4848";"0.0175"
"46.0000";"0.7667";"2.5039";"0.0171"
"46.2500";"0.7707";"2.5185";"0.0175"
"46.5000";"0.7748";"2.5315";"0.0182"
"46.7500";"0.7790";"2.5504";"0.0178"
"47.0000";"0.7834";"2.5740";"0.0178"
"47.2500";"0.7877";"2.5962";"0.0189"
"47.5000";"0.7917";"2.6110";"0.0188"
"47.7500";"0.7957";"2.6239";"0.0184"
"48.0000";"0.7998";"2.6402";"0.0190"
"48.2500";"0.8042";"2.6625";"0.0193"
"48.5000";"0.8085";"2.6854";"0.0192"
"48.7500";"0.8125";"2.7031";"0.0195"
"49.0000";"0.8166";"2.7177";"0.0198"
"49.2500";"0.8207";"2.7326";"0.0198"
"49.5000";"0.8250";"2.7528";"0.0199"
"49.7500";"0.8293";"2.7743";"0.0202"
"50.0000";"0.8334";"2.7953";"0.0205"
"50.2500";"0.8374";"2.8099";"0.0206"
"50.5000";"0.8415";"2.8247";"0.0207"
"50.7500";"0.8457";"2.8441";"0.0210"
"51.0000";"0.8501";"2.8657";"0.0211"
"51.2500";"0.8543";"2.8878";"0.0212"
"51.5000";"0.8584";"2.9038";"0.0216"
"51.7500";"0.8624";"2.9180";"0.0219"
"52.0000";"0.8665";"2.9338";"0.0217"
"52.2500";"0.8708";"2.9552";"0.0219"
"52.5000";"0.8752";"2.9791";"0.0223"
"52.7500";"0.8792";"2.9989";"0.0224"
"53.0000";"0.8833";"3.0130";"0.0225"
"53.2500";"0.8874";"3.0278";"0.0232"
"53.5000";"0.8915";"3.0453";"0.0228"
"53.7500";"0.8959";"3.0695";"0.0229"
"54.0000";"0.9001";"3.0925";"0.0235"
"54.2500";"0.9041";"3.1074";"0.0236"
"54.5000";"0.9082";"3.1229";"0.0232"
"54.7500";"0.9124";"3.1398";"0.0238"
"55.0000";"0.9168";"3.1629";"0.0242"
"55.2500";"0.9210";"3.1856";"0.0239"
"55.5000";"0.9250";"3.2029";"0.0244"
"55.7500";"0.9290";"3.2170";"0.0249"
"56.0000";"0.9332";"3.2335";"0.0245"
"56.2500";"0.9375";"3.2541";"0.0247"
"56.5000";"0.9418";"3.2803";"0.0257"
"56.7500";"0.9459";"3.2991";"0.0256"
"57.0000";"0.9499";"3.3134";"0.0254"
"57.2500";"0.9540";"3.3280";"0.0259"
"57.5000";"0.9582";"3.3468";"0.0262"
"57.7500";"0.9626";"3.3726";"0.0257"
"58.0000";"0.9668";"3.3947";"0.0262"
"58.2500";"0.9708";"3.4105";"0.0267"
"58.5000";"0.9748";"3.4249";"0.0265"
"58.7500";"0.9791";"3.4428";"0.0267"
"59.0000";"0.9834";"3.4655";"0.0270"
"59.2500";"0.9877";"3.4903";"0.0271"
"59.5000";"0.9916";"3.5076";"0.0273"
"59.7500";"0.9957";"3.5224";"0.0277"
"60.0000";"0.9999";"3.5393";"0.0277"
"60.2500";"1.0042";"3.5622";"0.0278"
"60.5000";"1.0085";"3.5876";"0.0286"
"60.7500";"1.0126";"3.6064";"0.0282"
"61.0000";"1.0166";"3.6220";"0.0284"
"61.2500";"1.0206";"3.6371";"0.0289"
"61.5000";"1.0249";"3.6579";"0.0288"
"61.7500";"1.0293";"3.6817";"0.0288"
"62.0000";"1.0335";"3.7047";"0.0294"
"62.2500";"1.0375";"3.7218";"0.0295"
"62.5000";"1.0416";"3.7370";"0.0295"
"62.7500";"1.0457";"3.7535";"0.0298"
"63.0000";"1.0500";"3.7772";"0.0301"
"63.2500";"1.0542";"3.8011";"0.0301"
"63.5000";"1.0584";"3.8217";"0.0303"
"63.7500";"1.0624";"3.8374";"0.0307"
"64.0000";"1.0665";"3.8533";"0.0305"
"64.2500";"1.0708";"3.8748";"0.0309"
"64.5000";"1.0751";"3.8991";"0.0311"
"64.7500";"1.0793";"3.9213";"0.0315"
"65.0000";"1.0832";"3.9382";"0.0315"
"65.2500";"1.0873";"3.9549";"0.0316"
"65.5000";"1.0915";"3.9729";"0.0318"
"65.7500";"1.0960";"3.9998";"0.0320"
"66.0000";"1.1002";"4.0232";"0.0322"
"66.2500";"1.1042";"4.0412";"0.0326"
"66.5000";"1.1082";"4.0554";"0.0327"
"66.7500";"1.1124";"4.0731";"0.0325"
"67.0000";"1.1166";"4.0957";"0.0331"
"67.2500";"1.1209";"4.1215";"0.0333"
"67.5000";"1.1251";"4.1439";"0.0332"
"67.7500";"1.1291";"4.1576";"0.0335"
"68.0000";"1.1332";"4.1744";"0.0339"
"68.2500";"1.1375";"4.1948";"0.0339"
"68.5000";"1.1418";"4.2207";"0.0340"
"68.7500";"1.1459";"4.2428";"0.0342"
"69.0000";"1.1499";"4.2604";"0.0345"
"69.2500";"1.1540";"4.2756";"0.0345"
"69.5000";"1.1583";"4.2954";"0.0348"
"69.7500";"1.1627";"4.3203";"0.0352"
"70.0000";"1.1668";"4.3448";"0.0350"
"70.2500";"1.1708";"4.3617";"0.0355"
"70.5000";"1.1749";"4.3774";"0.0355"
"70.7500";"1.1790";"4.3943";"0.0357"
"71.0000";"1.1833";"4.4174";"0.0358"
"71.2500";"1.1877";"4.4451";"0.0361"
"71.5000";"1.1917";"4.4643";"0.0364"
"71.7500";"1.1958";"4.4808";"0.0364"
"72.0000";"1.1998";"4.4946";"0.0365"
"72.2500";"1.2041";"4.5172";"0.0367"
"72.5000";"1.2084";"4.5416";"0.0371"
"72.7500";"1.2125";"4.5648";"0.0370"
"73.0000";"1.2166";"4.5829";"0.0374"
"73.2500";"1.2207";"4.5996";"0.0374"
"73.5000";"1.2250";"4.6171";"0.0377"
"73.7500";"1.2292";"4.6417";"0.0379"
"74.0000";"1.2334";"4.6650";"0.0380"
"74.2500";"1.2375";"4.6848";"0.0384"
"74.5000";"1.2415";"4.7025";"0.0385"
"74.7500";"1.2457";"4.7178";"0.0384"
"75.0000";"1.2500";"4.7407";"0.0390"
"75.2500";"1.2543";"4.7670";"0.0389"
"75.5000";"1.2585";"4.7881";"0.0391"
"75.7500";"1.2624";"4.8041";"0.0395"
"76.0000";"1.2665";"4.8211";"0.0393"
"76.2500";"1.2707";"4.8392";"0.0397"
"76.5000";"1.2751";"4.8653";"0.0401"
"76.7500";"1.2793";"4.8900";"0.0400"
"77.0000";"1.2833";"4.9083";"0.0402"
"77.2500";"1.2874";"4.9243";"0.0403"
"77.5000";"1.2915";"4.9406";"0.0405"
"77.7500";"1.2959";"4.9640";"0.0408"
"78.0000";"1.3001";"4.9901";"0.0409"
"78.2500";"1.3042";"5.0111";"0.0411"
"78.5000";"1.3082";"5.0273";"0.0415"
"78.7500";"1.3124";"5.0441";"0.0414"
"79.0000";"1.3167";"5.0659";"0.0415"
"79.2500";"1.3210";"5.0924";"0.0420"
"79.5000";"1.3250";"5.1133";"0.0421"
"79.7500";"1.3291";"5.1298";"0.0420"
"80.0000";"1.3331";"5.1462";"0.0425"
"80.2500";"1.3373";"5.1659";"0.0427"
"80.5000";"1.3418";"5.1920";"0.0423"
"80.7500";"1.3460";"5.2176";"0.0429"
"81.0000";"1.3501";"5.2350";"0.0432"
"81.2500";"1.3540";"5.2497";"0.0431"
"81.5000";"1.3582";"5.2674";"0.0435"
"81.7500";"1.3625";"5.2897";"0.0437"
"82.0000";"1.3668";"5.3187";"0.0438"
"82.2500";"1.3708";"5.3385";"0.0441"
"82.5000";"1.3749";"5.3554";"0.0444"
"82.7500";"1.3791";"5.3720";"0.0442"
"83.0000";"1.3834";"5.3926";"0.0447"
"83.2500";"1.3876";"5.4192";"0.0448"
"83.5000";"1.3917";"5.4411";"0.0449"
"83.7500";"1.3958";"5.4589";"0.0452"
"84.0000";"1.3998";"5.4750";"0.0453"
"84.2500";"1.4041";"5.4960";"0.0452"
"84.5000";"1.4085";"5.5206";"0.0455"
"84.7500";"1.4126";"5.5461";"0.0460"
"85.0000";"1.4167";"5.5631";"0.0459"
"85.2500";"1.4207";"5.5798";"0.0462"
"85.5000";"1.4248";"5.5967";"0.0465"
"85.7500";"1.4291";"5.6196";"0.0465"
"86.0000";"1.4335";"5.6466";"0.0467"
"86.2500";"1.4376";"5.6708";"0.0469"
"86.5000";"1.4417";"5.6869";"0.0470"
"86.7500";"1.4457";"5.7023";"0.0474"
"87.0000";"1.4499";"5.7217";"0.0475"
"87.2500";"1.4542";"5.7468";"0.0477"
"87.5000";"1.4584";"5.7736";"0.0480"
"87.7500";"1.4625";"5.7911";"0.0481"
"88.0000";"1.4665";"5.8076";"0.0481"
"88.2500";"1.4707";"5.8266";"0.0486"
"88.5000";"1.4751";"5.8505";"0.0484"
"88.7500";"1.4793";"5.8762";"0.0485"
"89.0000";"1.4833";"5.8965";"0.0492"
"89.2500";"1.4873";"5.9109";"0.0492"
"89.5000";"1.4915";"5.9291";"0.0492"
"89.7500";"1.4959";"5.9522";"0.0494"
"90.0000";"1.5002";"5.9799";"0.0499"
"90.2500";"1.5043";"6.0017";"0.0500"
"90.5000";"1.5083";"6.0176";"0.0499"
"90.7500";"1.5123";"6.0325";"0.0501"
"91.0000";"1.5166";"6.0538";"0.0504"
"91.2500";"1.5209";"6.0807";"0.0505"
"91.5000";"1.5251";"6.1057";"0.0509"
"91.7500";"1.5291";"6.1249";"0.0510"
"92.0000";"1.5332";"6.1398";"0.0510"
"92.2500";"1.5374";"6.1578";"0.0513"
"92.5000";"1.5417";"6.1816";"0.0515"
"92.7500";"1.5460";"6.2082";"0.0518"
"93.0000";"1.5500";"6.2276";"0.0520"
"93.2500";"1.5540";"6.2437";"0.0520"
"93.5000";"1.5582";"6.2606";"0.0522"
"93.7500";"1.5625";"6.2848";"0.0524"
"94.0000";"1.5668";"6.3117";"0.0526"
"94.2500";"1.5709";"6.3331";"0.0528"
"94.5000";"1.5750";"6.3493";"0.0526"
"94.7500";"1.5790";"6.3656";"0.0530"
"95.0000";"1.5832";"6.3852";"0.0535"
"95.2500";"1.5876";"6.4125";"0.0533"
"95.5000";"1.5918";"6.4383";"0.0536"
"95.7500";"1.5958";"6.4550";"0.0538"
"96.0000";"1.5999";"6.4701";"0.0538"
"96.2500";"1.6040";"6.4875";"0.0542"
"96.5000";"1.6084";"6.5112";"0.0544"
"96.7500";"1.6126";"6.5366";"0.0543"
"97.0000";"1.6167";"6.5587";"0.0547"
"97.2500";"1.6208";"6.5749";"0.0553"
"97.5000";"1.6249";"6.5923";"0.0547"
"97.7500";"1.6292";"6.6128";"0.0549"
"98.0000";"1.6335";"6.6384";"0.0556"
"98.2500";"1.6376";"6.6627";"0.0557"
"98.5000";"1.6416";"6.6799";"0.0555"
"98.7500";"1.6456";"6.6957";"0.0559"
"99.0000";"1.6499";"6.7154";"0.0561"
"99.2500";"1.6543";"6.7414";"0.0562"
"99.5000";"1.6585";"6.7668";"0.0562"
"99.7500";"1.6625";"6.7861";"0.0569"
"100.0000";"1.6665";"6.7994";"0.0568"
"100.2500";"1.6706";"6.8176";"0.0568"
"100.5000";"1.6750";"6.8403";"0.0573"
"100.7500";"1.6793";"6.8677";"0.0573"
"101.0000";"1.6834";"6.8906";"0.0575"
"101.2500";"1.6874";"6.9060";"0.0579"
"101.5000";"1.6915";"6.9212";"0.0575"
"101.7500";"1.6958";"6.9431";"0.0579"
"102.0000";"1.7002";"6.9688";"0.0583"
"102.2500";"1.7043";"6.9923";"0.0581"
"102.5000";"1.7082";"7.0103";"0.0585"
"102.7500";"1.7124";"7.0258";"0.0586"
"103.0000";"1.7166";"7.0450";"0.0588"
"103.2500";"1.7210";"7.0701";"0.0588"
"103.5000";"1.7252";"7.0961";"0.0593"
"103.7500";"1.7291";"7.1140";"0.0595"
"104.0000";"1.7332";"7.1306";"0.0596"
"104.2500";"1.7373";"7.1468";"0.0597"
"104.5000";"1.7416";"7.1707";"0.0597"
"104.7500";"1.7460";"7.1997";"0.0602"
"105.0000";"1.7501";"7.2204";"0.0604"
"105.2500";"1.7541";"7.2354";"0.0604"
"105.5000";"1.7582";"7.2512";"0.0605"
"105.7500";"1.7624";"7.2719";"0.0610"
"106.0000";"1.7667";"7.2972";"0.0610"
"106.2500";"1.7709";"7.3244";"0.0609"
"106.5000";"1.7749";"7.3412";"0.0614"
"106.7500";"1.7791";"7.3584";"0.0616"
"107.0000";"1.7833";"7.3772";"0.0617"
"107.2500";"1.7876";"7.4010";"0.0616"
"107.5000";"1.7918";"7.4259";"0.0621"
"107.7500";"1.7958";"7.4465";"0.0622"
"108.0000";"1.7999";"7.4628";"0.0621"
"108.2500";"1.8040";"7.4799";"0.0626"
"108.5000";"1.8084";"7.5027";"0.0627"
"108.7500";"1.8127";"7.5264";"0.0626"
"109.0000";"1.8168";"7.5525";"0.0632"
"109.2500";"1.8208";"7.5674";"0.0635"
"109.5000";"1.8249";"7.5840";"0.0631"
"109.7500";"1.8290";"7.6018";"0.0637"
"110.0000";"1.8334";"7.6287";"0.0641"
"110.2500";"1.8376";"7.6536";"0.0637"
"110.5000";"1.8417";"7.6743";"0.0639"
"110.7500";"1.8458";"7.6891";"0.0645"
"111.0000";"1.8498";"7.7054";"0.0645"
"111.2500";"1.8542";"7.7287";"0.0644"
"111.5000";"1.8584";"7.7561";"0.0651"
"111.7500";"1.8625";"7.7786";"0.0652"
"112.0000";"1.8665";"7.7945";"0.0649"
"112.2500";"1.8707";"7.8124";"0.0654"
"112.5000";"1.8750";"7.8312";"0.0655"
"112.7500";"1.8794";"7.8606";"0.0655"
"113.0000";"1.8834";"7.8820";"0.0660"
"113.2500";"1.8874";"7.8982";"0.0662"
"113.5000";"1.8915";"7.9131";"0.0662"
"113.7500";"1.8957";"7.9339";"0.0661"
"114.0000";"1.9001";"7.9606";"0.0667"
"114.2500";"1.9043";"7.9865";"0.0672"
"114.5000";"1.9084";"8.0049";"0.0668"
"114.7500";"1.9124";"8.0190";"0.0670"
"115.0000";"1.9165";"8.0375";"0.0675"
"115.2500";"1.9208";"8.0596";"0.0673"
"115.5000";"1.9251";"8.0880";"0.0676"
"115.7500";"1.9292";"8.1097";"0.0680"
"116.0000";"1.9333";"8.1276";"0.0684"
"116.2500";"1.9374";"8.1423";"0.0682"
"116.5000";"1.9417";"8.1647";"0.0685"
"116.7500";"1.9459";"8.1906";"0.0687"
"117.0000";"1.9501";"8.2140";"0.0688"
"117.2500";"1.9541";"8.2337";"0.0690"
"117.5000";"1.9581";"8.2499";"0.0692"
"117.7500";"1.9624";"8.2696";"0.0691"
"118.0000";"1.9668";"8.2957";"0.0695"
"118.2500";"1.9710";"8.3223";"0.0699"
"118.5000";"1.9750";"8.3390";"0.0699"
"118.7500";"1.9790";"8.3566";"0.0698"
"119.0000";"1.9831";"8.3725";"0.0702"
"119.2500";"1.9875";"8.3969";"0.0702"
"119.5000";"1.9918";"8.4238";"0.0705"
"119.7500";"1.9959";"8.4483";"0.0708"
"120.0000";"2.0000";"8.4636";"0.0712"
"120.2500";"2.0041";"8.4801";"0.0708"
"120.5000";"2.0082";"8.4998";"0.0714"
"120.7500";"2.0126";"8.5255";"0.0716"
"121.0000";"2.0167";"8.5525";"0.0714"
"121.2500";"2.0208";"8.5720";"0.0720"
"121.5000";"2.0249";"8.5892";"0.0723"
"121.7500";"2.0291";"8.6065";"0.0721"
"122.0000";"2.0334";"8.6309";"0.0723"
"122.2500";"2.0377";"8.6578";"0.0727"
"122.5000";"2.0417";"8.6790";"0.0729"
"122.7500";"2.0457";"8.6943";"0.0728"
"123.0000";"2.0498";"8.7125";"0.0733"
"123.2500";"2.0541";"8.7341";"0.0735"
"123.5000";"2.0585";"8.7642";"0.0733"
"123.7500";"2.0626";"8.7879";"0.0737"
"124.0000";"2.0666";"8.8023";"0.0739"
"124.2500";"2.0706";"8.8184";"0.0737"
"124.5000";"2.0749";"8.8404";"0.0743"
"124.7500";"2.0793";"8.8677";"0.0744"
"125.0000";"2.0835";"8.8951";"0.0746"
"125.2500";"2.0875";"8.9143";"0.0746"
"125.5000";"2.0916";"8.9298";"0.0750"
"125.7500";"2.0958";"8.9482";"0.0753"
"126.0000";"2.1001";"8.9738";"0.0751"
"126.2500";"2.1043";"9.0011";"0.0756"
"126.5000";"2.1083";"9.0212";"0.0760"
"126.7500";"2.1124";"9.0386";"0.0757"
"127.0000";"2.1166";"9.0566";"0.0759"
"127.2500";"2.1209";"9.0803";"0.0762"
"127.5000";"2.1252";"9.1082";"0.0764"
"127.7500";"2.1293";"9.1319";"0.0765"
"128.0000";"2.1332";"9.1476";"0.0767"
"128.2500";"2.1373";"9.1650";"0.0772"
"128.5000";"2.1416";"9.1873";"0.0769"
"128.7500";"2.1459";"9.2128";"0.0770"
"129.0000";"2.1502";"9.2410";"0.0780"
"129.2500";"2.1542";"9.2596";"0.0778"
"129.5000";"2.1582";"9.2757";"0.0774"
"129.7500";"2.1624";"9.2930";"0.0781"
"130.0000";"2.1667";"9.3190";"0.0784"
"130.2500";"2.1709";"9.3457";"0.0782"
"130.5000";"2.1750";"9.3688";"0.0785"
"130.7500";"2.1791";"9.3871";"0.0793"
"131.0000";"2.1832";"9.4053";"0.0788"
"131.2500";"2.1875";"9.4276";"0.0789"
"131.5000";"2.1918";"9.4530";"0.0795"
"131.7500";"2.1959";"9.4783";"0.0797"
"132.0000";"2.1999";"9.4955";"0.0797"
"132.2500";"2.2040";"9.5140";"0.0797"
"132.5000";"2.2082";"9.5334";"0.0801"
"132.7500";"2.2126";"9.5605";"0.0803"
"133.0000";"2.2168";"9.5874";"0.0803"
"133.2500";"2.2209";"9.6079";"0.0807"
"133.5000";"2.2249";"9.6227";"0.0808"
"133.7500";"2.2290";"9.6403";"0.0808"
"134.0000";"2.2333";"9.6635";"0.0809"
"134.2500";"2.2376";"9.6928";"0.0814"
"134.5000";"2.2418";"9.7179";"0.0815"
"134.7500";"2.2457";"9.7341";"0.0816"
"135.0000";"2.2499";"9.7509";"0.0820"
"135.2500";"2.2541";"9.7704";"0.0821"
"135.5000";"2.2585";"9.7995";"0.0821"
"135.7500";"2.2625";"9.8263";"0.0826"
"136.0000";"2.2666";"9.8443";"0.0830"
"136.2500";"2.2707";"9.8610";"0.0828"
"136.5000";"2.2750";"9.8818";"0.0827"
"136.7500";"2.2793";"9.9085";"0.0836"
"137.0000";"2.2835";"9.9349";"0.0834"
"137.2500";"2.2875";"9.9540";"0.0834"
"137.5000";"2.2915";"9.9707";"0.0838"
"137.7500";"2.2957";"9.9892";"0.0842"
"138.0000";"2.3000";"10.0125";"0.0840"
"138.2500";"2.3043";"10.0431";"0.0840"
"138.5000";"2.3084";"10.0646";"0.0846"
"138.7500";"2.3125";"10.0824";"0.0850"
"139.0000";"2.3165";"10.0985";"0.0848"
"139.2500";"2.3208";"10.1203";"0.0850"
"139.5000";"2.3251";"10.1458";"0.0853"
"139.7500";"2.3292";"10.1731";"0.0855"
"140.0000";"2.3333";"10.1937";"0.0858"
"140.2500";"2.3374";"10.2103";"0.0860"
"140.5000";"2.3416";"10.2305";"0.0860"
"140.7500";"2.3459";"10.2546";"0.0862"
"141.0000";"2.3501";"10.2820";"0.0865"
"141.2500";"2.3542";"10.3027";"0.0866"
"141.5000";"2.3582";"10.3220";"0.0868"
"141.7500";"2.3623";"10.3383";"0.0869"
"142.0000";"2.3667";"10.3635";"0.0871"
"142.2500";"2.3710";"10.3921";"0.0876"
"142.5000";"2.3751";"10.4161";"0.0875"
"142.7500";"2.3791";"10.4326";"0.0877"
"143.0000";"2.3832";"10.4512";"0.0878"
"143.2500";"2.3873";"10.4709";"0.0882"
"143.5000";"2.3917";"10.4982";"0.0883"
"143.7500";"2.3959";"10.5258";"0.0885"
"144.0000";"2.4000";"10.5474";"0.0887"
"144.2500";"2.4041";"10.5649";"0.0888"
"144.5000";"2.4082";"10.5819";"0.0890"
"144.7500";"2.4125";"10.6061";"0.0892"
"145.0000";"2.4168";"10.6354";"0.0893"
"145.2500";"2.4208";"10.6593";"0.0899"
"145.5000";"2.4249";"10.6771";"0.0898"
"145.7500";"2.4290";"10.6960";"0.0902"
"146.0000";"2.4334";"10.7176";"0.0904"
"146.2500";"2.4377";"10.7479";"0.0906"
"146.5000";"2.4417";"10.7724";"0.0906"
"146.7500";"2.4458";"10.7907";"0.0912"
"147.0000";"2.4497";"10.8053";"0.0915"
"147.2500";"2.4540";"10.8276";"0.0912"
"147.5000";"2.4584";"10.8567";"0.0916"
"147.7500";"2.4627";"10.8858";"0.0919"
"148.0000";"2.4667";"10.9062";"0.0919"
"148.2500";"2.4707";"10.9222";"0.0921"
"148.5000";"2.4748";"10.9403";"0.0922"
"148.7500";"2.4792";"10.9661";"0.0926"
"149.0000";"2.4835";"10.9968";"0.0925"
"149.2500";"2.4875";"11.0206";"0.0929"
"149.5000";"2.4916";"11.0386";"0.0934"
"149.7500";"2.4957";"11.0564";"0.0931"
"150.0000";"2.5000";"11.0805";"0.0934"
"150.2500";"2.5042";"11.1062";"0.0939"
"150.5000";"2.5084";"11.1337";"0.0940"
"150.7500";"2.5125";"11.1539";"0.0939"
"151.0000";"2.5165";"11.1711";"0.0945"
"151.2500";"2.5207";"11.1933";"0.0945"
"151.5000";"2.5251";"11.2216";"0.0944"
"151.7500";"2.5293";"11.2496";"0.0950"
"152.0000";"2.5333";"11.2702";"0.0954"
"152.2500";"2.5374";"11.2888";"0.0952"
"152.5000";"2.5415";"11.3066";"0.0954"
"152.7500";"2.5458";"11.3332";"0.0960"
"153.0000";"2.5501";"11.3630";"0.0960"
"153.2500";"2.5542";"11.3898";"0.0960"
"153.5000";"2.5583";"11.4065";"0.0966"
"153.7500";"2.5623";"11.4250";"0.0966"
"154.0000";"2.5665";"11.4462";"0.0965"
"154.2500";"2.5709";"11.4750";"0.0972"
"154.5000";"2.5751";"11.5033";"0.0974"
"154.7500";"2.5791";"11.5259";"0.0972"
"155.0000";"2.5832";"11.5440";"0.0973"
"155.2500";"2.5874";"11.5646";"0.0982"
"155.5000";"2.5918";"11.5911";"0.0983"
"155.7500";"2.5960";"11.6198";"0.0979"
"156.0000";"2.6000";"11.6426";"0.0987"
"156.2500";"2.6040";"11.6602";"0.0990"
"156.5000";"2.6082";"11.6809";"0.0986"
"156.7500";"2.6124";"11.7029";"0.0986"
"157.0000";"2.6168";"11.7361";"0.0998"
"157.2500";"2.6209";"11.7608";"0.0995"
"157.5000";"2.6250";"11.7789";"0.0993"
"157.7500";"2.6289";"11.7947";"0.1000"
"158.0000";"2.6332";"11.8187";"0.1001"
"158.2500";"2.6376";"11.8465";"0.1001"
"158.5000";"2.6418";"11.8772";"0.1005"
"158.7500";"2.6458";"11.8981";"0.1010"
"159.0000";"2.6499";"11.9152";"0.1008"
"159.2500";"2.6541";"11.9351";"0.1007"
"159.5000";"2.6584";"11.9622";"0.1013"
"159.7500";"2.6626";"11.9928";"0.1016"
"160.0000";"2.6666";"12.0136";"0.1018"
"160.2500";"2.6707";"12.0328";"0.1019"
"160.5000";"2.6748";"12.0513";"0.1019"
"160.7500";"2.6792";"12.0797";"0.1023"
"161.0000";"2.6835";"12.1072";"0.1027"
"161.2500";"2.6876";"12.1331";"0.1029"
"161.5000";"2.6916";"12.1513";"0.1030"
"161.7500";"2.6957";"12.1699";"0.1033"
"162.0000";"2.6999";"12.1933";"0.1038"
"162.2500";"2.7042";"12.2210";"0.1036"
"162.5000";"2.7085";"12.2520";"0.1038"
"162.7500";"2.7125";"12.2725";"0.1041"
"163.0000";"2.7166";"12.2902";"0.1045"
"163.2500";"2.7207";"12.3092";"0.1044"
"163.5000";"2.7250";"12.3366";"0.1047"
"163.7500";"2.7293";"12.3649";"0.1049"
"164.0000";"2.7334";"12.3917";"0.1054"
"164.2500";"2.7374";"12.4113";"0.1052"
"164.5000";"2.7415";"12.4299";"0.1054"
"164.7500";"2.7458";"12.4542";"0.1063"
"165.0000";"2.7502";"12.4827";"0.1060"
"165.2500";"2.7543";"12.5092";"0.1061"
"165.5000";"2.7582";"12.5288";"0.1065"
"165.7500";"2.7623";"12.5491";"0.1067"
"166.0000";"2.7666";"12.5703";"0.1064"
"166.2500";"2.7710";"12.6005";"0.1076"
"166.5000";"2.7751";"12.6283";"0.1071"
"166.7500";"2.7792";"12.6517";"0.1073"
"167.0000";"2.7832";"12.6683";"0.1078"
"167.2500";"2.7873";"12.6889";"0.1082"
"167.5000";"2.7916";"12.7139";"0.1082"
"167.7500";"2.7959";"12.7452";"0.1085"
"168.0000";"2.8001";"12.7725";"0.1089"
"168.2500";"2.8041";"12.7913";"0.1086"
"168.5000";"2.8082";"12.8110";"0.1091"
"168.7500";"2.8124";"12.8309";"0.1094"
"169.0000";"2.8168";"12.8629";"0.1095"
"169.2500";"2.8209";"12.8898";"0.1097"
"169.5000";"2.8250";"12.9119";"0.1099"
"169.7500";"2.8290";"12.9285";"0.1103"
"170.0000";"2.8333";"12.9524";"0.1103"
"170.2500";"2.8376";"12.9800";"0.1107"
"170.5000";"2.8419";"13.0102";"0.1106"
"170.7500";"2.8458";"13.0308";"0.1113"
"171.0000";"2.8498";"13.0495";"0.1114"
"171.2500";"2.8540";"13.0696";"0.1113"
"171.5000";"2.8583";"13.0950";"0.1118"
"171.7500";"2.8627";"13.1292";"0.1120"
"172.0000";"2.8668";"13.1528";"0.1121"
"172.2500";"2.8708";"13.1718";"0.1125"
"172.5000";"2.8748";"13.1890";"0.1126"
"172.7500";"2.8792";"13.2145";"0.1124"
"173.0000";"2.8833";"13.2417";"0.1129"
"173.2500";"2.8875";"13.2714";"0.1134"
"173.5000";"2.8916";"13.2941";"0.1136"
"173.7500";"2.8957";"13.3145";"0.1135"
"174.0000";"2.8999";"13.3352";"0.1141"
"174.2500";"2.9042";"13.3616";"0.1142"
"174.5000";"2.9084";"13.3907";"0.1143"
"174.7500";"2.9125";"13.4162";"0.1145"
"175.0000";"2.9166";"13.4371";"0.1153"
"175.2500";"2.9206";"13.4556";"0.1150"
"175.5000";"2.9250";"13.4841";"0.1153"
"175.7500";"2.9293";"13.5124";"0.1158"
"176.0000";"2.9335";"13.5407";"0.1161"
"176.2500";"2.9374";"13.5588";"0.1156"
"176.5000";"2.9415";"13.5797";"0.1163"
"176.7500";"2.9456";"13.5986";"0.1164"
"177.0000";"2.9501";"13.6302";"0.1163"
"177.2500";"2.9543";"13.6610";"0.1170"
"177.5000";"2.9583";"13.6841";"0.1174"
"177.7500";"2.9624";"13.7028";"0.1173"
"178.0000";"2.9665";"13.7221";"0.1172"
"178.2500";"2.9709";"13.7491";"0.1180"
"178.5000";"2.9751";"13.7789";"0.1182"
"178.7500";"2.9792";"13.8048";"0.1181"
"179.0000";"2.9832";"13.8239";"0.1186"
"179.2500";"2.9874";"13.8465";"0.1187"
"179.5000";"2.9917";"13.8679";"0.1191"
"179.7500";"2.9960";"13.9001";"0.1191"
"180.0000";"3.0000";"13.9271";"0.1196"
"180.2500";"3.0041";"13.9483";"0.1196"
"180.5000";"3.0081";"13.9653";"0.1198"
"180.7500";"3.0123";"13.9896";"0.1203"
"181.0000";"3.0168";"14.0194";"0.1205"
"181.2500";"3.0210";"14.0510";"0.1206"
"181.5000";"3.0251";"14.0736";"0.1210"
"181.7500";"3.0290";"14.0915";"0.1210"
"182.0000";"3.0332";"14.1115";"0.1210"
"182.2500";"3.0375";"14.1382";"0.1220"
"182.5000";"3.0418";"14.1720";"0.1220"
"182.7500";"3.0459";"14.1983";"0.1221"
"183.0000";"3.0499";"14.2189";"0.1223"
"183.2500";"3.0541";"14.2374";"0.1227"
"183.5000";"3.0584";"14.2650";"0.1227"
"183.7500";"3.0626";"14.2942";"0.1230"
"184.0000";"3.0667";"14.3214";"0.1233"
"184.2500";"3.0708";"14.3427";"0.1235"
"184.5000";"3.0748";"14.3634";"0.1237"
"184.7500";"3.0791";"14.3878";"0.1239"
"185.0000";"3.0835";"14.4159";"0.1244"
"185.2500";"3.0877";"14.4464";"0.1245"
"185.5000";"3.0916";"14.4675";"0.1249"
"185.7500";"3.0957";"14.4877";"0.1249"
"186.0000";"3.0998";"14.5069";"0.1249"
"186.2500";"3.1042";"14.5353";"0.1257"
"186.5000";"3.1084";"14.5661";"0.1259"
"186.7500";"3.1126";"14.5955";"0.1259"
"187.0000";"3.1167";"14.6160";"0.1262"
"187.2500";"3.1207";"14.6343";"0.1267"
"187.5000";"3.1249";"14.6565";"0.1265"
"187.7500";"3.1292";"14.6870";"0.1270"
"188.0000";"3.1334";"14.7184";"0.1274"
"188.2500";"3.1374";"14.7417";"0.1274"
"188.5000";"3.1415";"14.7615";"0.1277"
"188.7500";"3.1457";"14.7833";"0.1281"
"189.0000";"3.1501";"14.8131";"0.1281"
"189.2500";"3.1544";"14.8439";"0.1282"
"189.5000";"3.1583";"14.8670";"0.1291"
"189.7500";"3.1624";"14.8859";"0.1290"
"190.0000";"3.1665";"14.9081";"0.1288"
"190.2500";"3.1708";"14.9340";"0.1295"
"190.5000";"3.1752";"14.9654";"0.1302"
"190.7500";"3.1793";"14.9927";"0.1297"
"191.0000";"3.1833";"15.0128";"0.1302"
"191.2500";"3.1873";"15.0299";"0.1307"
"191.5000";"3.1916";"15.0539";"0.1307"
"191.7500";"3.1959";"15.0842";"0.1308"
"192.0000";"3.2001";"15.1163";"0.1314"
"192.2500";"3.2042";"15.1401";"0.1316"
"192.5000";"3.2082";"15.1585";"0.1315"
"192.7500";"3.2124";"15.1801";"0.1320"
"193.0000";"3.2167";"15.2061";"0.1324"
"193.2500";"3.2209";"15.2366";"0.1327"
"193.5000";"3.2250";"15.2608";"0.1332"
"193.7500";"3.2290";"15.2794";"0.1338"
"194.0000";"3.2331";"15.2981";"0.1339"
"194.2500";"3.2375";"15.3213";"0.1345"
"194.5000";"3.2419";"15.3432";"0.1357"
"194.7500";"3.2459";"15.3452";"0.1366"
"195.0000";"3.2499";"15.2558";"0.1346"
"195.2500";"3.2540";"14.8428";"0.1325"
"195.5000";"3.2583";"14.5488";"0.1297"
"195.7500";"3.2626";"14.3934";"0.1280"
"196.0000";"3.2668";"14.3046";"0.1272"
"196.2500";"3.2709";"14.2415";"0.1264"
"196.5000";"3.2749";"14.1892";"0.1259"
"196.7500";"3.2791";"14.1504";"0.1255"
"197.0000";"3.2833";"14.1270";"0.1262"
"197.2500";"3.2876";"14.1057";"0.1271"
"197.5000";"3.2917";"14.0981";"0.1282"
"197.7500";"3.2958";"14.0815";"0.1296"
"198.0000";"3.2999";"14.0603";"0.1309"
"198.2500";"3.3042";"13.9813";"0.1300"
"198.5000";"3.3085";"13.8275";"0.1303"
"198.7500";"3.3126";"13.7365";"0.1305"
"199.0000";"3.3166";"13.6801";"0.1316"
"199.2500";"3.3207";"13.6466";"0.1328"
"199.5000";"3.3249";"13.6275";"0.1342"
"199.7500";"3.3293";"13.6288";"0.1360"
"200.0000";"3.3335";"13.6379";"0.1380"
"200.2500";"3.3376";"13.6440";"0.1397"
"200.5000";"3.3415";"13.6434";"0.1419"
"200.7500";"3.3456";"13.6507";"0.1439"
"201.0000";"3.3500";"13.6615";"0.1461"
"201.2500";"3.3543";"13.6797";"0.1485"
"201.5000";"3.3584";"13.6819";"0.1517"
"201.7500";"3.3624";"13.6671";"0.1550"
"202.0000";"3.3665";"13.6614";"0.1583"
"202.2500";"3.3708";"13.6606";"0.1617"
"202.5000";"3.3752";"13.6621";"0.1649"
"202.7500";"3.3792";"13.6550";"0.1681"
"203.0000";"3.3833";"13.6501";"0.1710"
"203.2500";"3.3874";"13.6471";"0.1744"
"203.5000";"3.3916";"13.6533";"0.1771"
"203.7500";"3.3959";"13.6643";"0.1806"
"204.0000";"3.4002";"13.6801";"0.1838"
"204.2500";"3.4042";"13.6855";"0.1873"
"204.5000";"3.4082";"13.6836";"0.1909"
"204.7500";"3.4123";"13.6794";"0.1955"
"205.0000";"3.4166";"13.6749";"0.2006"
"205.2500";"3.4210";"13.6509";"0.2070"
"205.5000";"3.4251";"13.6317";"0.2127"
"205.7500";"3.4291";"13.6175";"0.2180"
"206.0000";"3.4332";"13.6096";"0.2231"
"206.2500";"3.4374";"13.6135";"0.2278"
"206.5000";"3.4417";"13.6233";"0.2335"
"206.7500";"3.4459";"13.6347";"0.2386"
"207.0000";"3.4500";"13.6338";"0.2443"
"207.2500";"3.4541";"13.6274";"0.2496"
"207.5000";"3.4583";"13.6190";"0.2555"
"207.7500";"3.4626";"13.6056";"0.2614"
"208.0000";"3.4668";"13.5854";"0.2680"
"208.2500";"3.4709";"13.5704";"0.2743"
"208.5000";"3.4749";"13.5548";"0.2804"
"208.7500";"3.4790";"13.5382";"0.2865"
"209.0000";"3.4834";"13.5337";"0.2927"
"209.2500";"3.4877";"13.5367";"0.2986"
"209.5000";"3.4918";"13.5415";"0.3046"
"209.7500";"3.4958";"13.5386";"0.3107"
"210.0000";"3.4999";"13.5364";"0.3174"
"210.2500";"3.5040";"13.5341";"0.3236"
"210.5000";"3.5084";"13.5436";"0.3304"
"210.7500";"3.5126";"13.5428";"0.3383"
"211.0000";"3.5167";"13.5108";"0.3469"
"211.2500";"3.5207";"13.4825";"0.3555"
"211.5000";"3.5249";"13.4565";"0.3639"
"211.7500";"3.5291";"13.4429";"0.3724"
"212.0000";"3.5335";"13.4445";"0.3801"
"212.2500";"3.5375";"13.4418";"0.3883"
"212.5000";"3.5415";"13.4267";"0.3965"
"212.7500";"3.5457";"13.4201";"0.4044"
"213.0000";"3.5500";"13.4205";"0.4123"
"213.2500";"3.5543";"13.4274";"0.4203"
"213.5000";"3.5584";"13.4194";"0.4283"
"213.7500";"3.5624";"13.3991";"0.4372"
"214.0000";"3.5664";"13.3831";"0.4453"
"214.2500";"3.5707";"13.3823";"0.4536"
"214.5000";"3.5751";"13.3888";"0.4615"
"214.7500";"3.5793";"13.4027";"0.4693"
"215.0000";"3.5833";"13.4102";"0.4767"
"215.2500";"3.5874";"13.4145";"0.4845"
"215.5000";"3.5915";"13.4153";"0.4924"
"215.7500";"3.5958";"13.4247";"0.5001"
"216.0000";"3.6001";"13.4423";"0.5079"
"216.2500";"3.6042";"13.4512";"0.5157"
"216.5000";"3.6083";"13.4466";"0.5238"
"216.7500";"3.6124";"13.4102";"0.5331"
"217.0000";"3.6167";"13.3975";"0.5416"
"217.2500";"3.6209";"13.3864";"0.5503"
"217.5000";"3.6251";"13.3696";"0.5594"
"217.7500";"3.6291";"13.3555";"0.5677"
"218.0000";"3.6331";"13.3517";"0.5760"
"218.2500";"3.6374";"13.3589";"0.5836"
"218.5000";"3.6418";"13.3782";"0.5914"
"218.7500";"3.6460";"13.4030";"0.5985"
"219.0000";"3.6500";"13.4217";"0.6057"
"219.2500";"3.6541";"13.4393";"0.6129"
"219.5000";"3.6581";"13.4562";"0.6201"
"219.7500";"3.6625";"13.4841";"0.6271"
"220.0000";"3.6667";"13.5126";"0.6342"
"220.2500";"3.6709";"13.5416";"0.6411"
"220.5000";"3.6750";"13.5591";"0.6482"
"220.7500";"3.6791";"13.5768";"0.6551"
"221.0000";"3.6832";"13.5925";"0.6618"
"221.2500";"3.6875";"13.6145";"0.6690"
"221.5000";"3.6918";"13.6368";"0.6759"
"221.7500";"3.6958";"13.6517";"0.6830"
"222.0000";"3.6999";"13.6599";"0.6897"
"222.2500";"3.7040";"13.6647";"0.6964"
"222.5000";"3.7085";"13.6736";"0.7034"
"222.7500";"3.7126";"13.6771";"0.7103"
"223.0000";"3.7167";"13.6700";"0.7177"
"223.2500";"3.7207";"13.6240";"0.7264"
"223.5000";"3.7248";"13.5680";"0.7350"
"223.7500";"3.7291";"13.5247";"0.7440"
"224.0000";"3.7335";"13.4977";"0.7529"
"224.2500";"3.7376";"13.4675";"0.7618"
"224.5000";"3.7416";"13.4293";"0.7706"
"224.7500";"3.7456";"13.3985";"0.7795"
"225.0000";"3.7499";"13.3789";"0.7878"
"225.2500";"3.7543";"13.3581";"0.7971"
"225.5000";"3.7585";"13.3226";"0.8063"
"225.7500";"3.7625";"13.2946";"0.8155"
"226.0000";"3.7666";"13.2726";"0.8240"
"226.2500";"3.7708";"13.2635";"0.8327"
"226.5000";"3.7750";"13.2644";"0.8408"
"226.7500";"3.7793";"13.2836";"0.8484"
"227.0000";"3.7833";"13.3007";"0.8560"
"227.2500";"3.7874";"13.3140";"0.8632"
"227.5000";"3.7915";"13.3248";"0.8710"
"227.7500";"3.7958";"13.3390";"0.8785"
"228.0000";"3.8002";"13.3535";"0.8870"
"228.2500";"3.8043";"13.3584";"0.8955"
"228.5000";"3.8083";"13.3584";"0.9038"
"228.7500";"3.8123";"13.3552";"0.9118"
"229.0000";"3.8166";"13.3556";"0.9201"
"229.2500";"3.8209";"13.3458";"0.9289"
"229.5000";"3.8251";"13.3450";"0.9378"
"229.7500";"3.8292";"13.3401";"0.9460"
"230.0000";"3.8332";"13.3333";"0.9541"
"230.2500";"3.8373";"13.3298";"0.9622"
"230.5000";"3.8417";"13.3347";"0.9703"
"230.7500";"3.8459";"13.3418";"0.9785"
"231.0000";"3.8500";"13.3450";"0.9869"
"231.2500";"3.8541";"13.3389";"0.9949"
"231.5000";"3.8582";"13.3245";"1.0040"
"231.7500";"3.8626";"13.3131";"1.0128"
"232.0000";"3.8668";"13.3065";"1.0215"
"232.2500";"3.8710";"13.3041";"1.0297"
"232.5000";"3.8749";"13.2888";"1.0381"
"232.7500";"3.8790";"13.2806";"1.0464"
"233.0000";"3.8832";"13.2763";"1.0546"
"233.2500";"3.8876";"13.2852";"1.0625"
"233.5000";"3.8918";"13.2946";"1.0705"
"233.7500";"3.8959";"13.3002";"1.0779"
"234.0000";"3.8999";"13.2983";"1.0859"
"234.2500";"3.9040";"13.3024";"1.0933"
"234.4720";"3.9077";"13.3098";"1.1000"
"234.6740";"3.9092";"13.2720";"1.1000"
"234.9240";"3.9091";"13.1660";"1.1000"
"235.1740";"3.9089";"13.0876";"1.1000"
"235.4240";"3.9087";"13.0212";"1.1000"
"235.6740";"3.9085";"12.9594";"1.1000"
"235.9240";"3.9084";"12.9059";"1.1000"
"236.1740";"3.9084";"12.8630";"1.1000"
"236.4240";"3.9084";"12.8276";"1.1000"
"236.6740";"3.9084";"12.7973";"1.1000"
"236.9240";"3.9084";"12.7694";"1.1000"
"237.1740";"3.9084";"12.7458";"1.1000"
"237.4240";"3.9084";"12.7246";"1.1000"
"237.6740";"3.9084";"12.7056";"1.1000"
"237.9240";"3.9084";"12.6879";"1.1000"
"238.1740";"3.9084";"12.6719";"1.1000"
"238.4240";"3.9084";"12.6576";"1.1000"
"238.6740";"3.9084";"12.6445";"1.1000"
"238.9240";"3.9084";"12.6316";"1.1000"
"239.1740";"3.9084";"12.6191";"1.1000"
"239.4240";"3.9083";"12.6083";"1.1000"
"239.6740";"3.9083";"12.5980";"1.1000"
"239.9240";"3.9083";"12.5876";"1.1000"
"240.1740";"3.9083";"12.5783";"1.1000"
"240.4240";"3.9083";"12.5702";"1.1000"
"240.6740";"3.9083";"12.5623";"1.1000"
"240.9240";"3.9083";"12.5539";"1.1000"
"241.1740";"3.9083";"12.5457";"1.1000"
"241.4240";"3.9083";"12.5393";"1.1000"
"241.6740";"3.9083";"12.5319";"1.1000"
"241.9240";"3.9083";"12.5253";"1.1000"
"242.1740";"3.9083";"12.5179";"1.1000"
"242.4240";"3.9083";"12.5118";"1.1000"
"242.6740";"3.9083";"12.5067";"1.1000"
"242.9240";"3.9084";"12.5023";"1.1000"
"243.1740";"3.9084";"12.4962";"1.1000"
"243.4240";"3.9084";"12.4911";"1.1000"
"243.6740";"3.9084";"12.4862";"1.1000"
"243.9240";"3.9084";"12.4806";"1.1000"
"244.1740";"3.9084";"12.4768";"1.1000"
"244.4240";"3.9084";"12.4714";"1.1000"
"244.6740";"3.9084";"12.4673";"1.1000"
"244.9240";"3.9084";"12.4625";"1.1000"
"245.1740";"3.9084";"12.4581";"1.1000"
"245.4240";"3.9084";"12.4535";"1.1000"
"245.6740";"3.9084";"12.4497";"1.1000"
"245.9240";"3.9084";"12.4459";"1.1000"
"246.1740";"3.9084";"12.4416";"1.1000"
"246.4240";"3.9084";"12.4376";"1.1000"
"246.6740";"3.9084";"12.4342";"1.1000"
"246.9240";"3.9084";"12.4310";"1.1000"
"247.1740";"3.9084";"12.4271";"1.1000"
"247.4240";"3.9084";"12.4233";"1.1000"
"247.6740";"3.9084";"12.4208";"1.1000"
"247.9240";"3.9084";"12.4172";"1.1000"
"248.1740";"3.9084";"12.4145";"1.1000"
"248.4240";"3.9084";"12.4109";"1.1000"
"248.6740";"3.9084";"12.4084";"1.1000"
"248.9240";"3.9084";"12.4059";"1.1000"
"249.1740";"3.9084";"12.4030";"1.1000"
"249.4240";"3.9084";"12.4000";"1.1000"
"249.6740";"3.9084";"12.3971";"1.1000"
"249.9240";"3.9084";"12.3949";"1.1000"
"250.1740";"3.9084";"12.3927";"1.1000"
"250.4240";"3.9084";"12.3899";"1.1000"
"250.6740";"3.9084";"12.3864";"1.1000"
"250.9240";"3.9084";"12.3843";"1.1000"
"251.1740";"3.9084";"12.3820";"1.1000"
"251.4240";"3.9084";"12.3800";"1.1000"
"251.6740";"3.9084";"12.3771";"1.1000"
"251.9240";"3.9084";"12.3751";"1.1000"
"252.1740";"3.9084";"12.3730";"1.1000"
"252.4240";"3.9084";"12.3713";"1.1000"
"252.6740";"3.9084";"12.3677";"1.1000"
"252.9240";"3.9084";"12.3665";"1.1000"
"253.1740";"3.9084";"12.3643";"1.1000"
"253.4240";"3.9084";"12.3622";"1.1000"
"253.6740";"3.9084";"12.3605";"1.1000"
"253.9240";"3.9084";"12.3578";"1.1000"
"254.1740";"3.9084";"12.3564";"1.1000"
"254.4240";"3.9084";"12.3548";"1.1000"
"254.5920";"3.9084";"12.3532";"1.1000"
"254.8420";"3.9694";"14.0060";"1.1000"
"255.0920";"4.0606";"14.6172";"1.1000"
"255.3420";"4.1438";"14.6393";"1.1000"
"255.5920";"4.2271";"14.5957";"1.1000"
"255.8420";"4.3104";"14.5979";"1.1000"
"256.0920";"4.3937";"14.4918";"1.1000"
"256.3420";"4.4771";"14.4853";"1.1000"
"256.5920";"4.5605";"14.4113";"1.1000"
"256.8420";"4.6437";"14.1745";"1.1000"
"257.0920";"4.7270";"15.0251";"1.1000"
"257.3420";"4.8103";"15.3543";"1.1000"
"257.5920";"4.8938";"15.5853";"1.1000"
"257.8420";"4.9770";"15.7892";"1.1000"
"258.0920";"5.0603";"15.9765";"1.1000"
"258.3420";"5.1438";"16.1504";"1.1000"
"258.5920";"5.2271";"16.3089";"1.1000"
"258.8420";"5.3103";"16.4586";"1.1000"
"259.0920";"5.3936";"16.5988";"1.1000"
"259.3420";"5.4770";"16.7336";"1.1000"
"259.5920";"5.5604";"16.8671";"1.1000"
"259.8420";"5.6438";"16.9934";"1.1000"
"260.0920";"5.7271";"17.1167";"1.1000"
"260.3420";"5.8103";"17.2387";"1.1000"
"260.5920";"5.8937";"17.3546";"1.1000"
"260.8420";"5.9769";"17.4702";"1.1000"
"261.0920";"6.0604";"17.5864";"1.1000"
"261.3420";"6.1438";"17.6954";"1.1000"
"261.5920";"6.2270";"17.8043";"1.1000"
"261.8420";"6.3103";"17.9116";"1.1000"
"262.0920";"6.3936";"18.0146";"1.1000"
"262.3420";"6.4770";"18.1178";"1.1000"
"262.5920";"6.5604";"18.2196";"1.1000"
"262.8420";"6.6437";"18.3169";"1.1000"
"263.0920";"6.7271";"18.4134";"1.1000"
"263.3420";"6.8104";"18.5073";"1.1000"
"263.5920";"6.8937";"18.6006";"1.1000"
"263.8420";"6.9771";"18.6915";"1.1000"
"264.0920";"7.0603";"18.7805";"1.1000"
"264.3420";"7.1437";"18.8684";"1.1000"
"264.5920";"7.2271";"18.9524";"1.1000"
"264.8420";"7.3104";"19.0355";"1.1000"
"265.0920";"7.3937";"19.1171";"1.1000"
"265.3420";"7.4770";"19.1979";"1.1000"
"265.5920";"7.5604";"19.2761";"1.1000"
"265.8420";"7.6438";"19.3538";"1.1000"
"266.0920";"7.7271";"19.4290";"1.1000"
"266.3420";"7.8104";"19.5020";"1.1000"
"266.5920";"7.8936";"19.5707";"1.1000"
"266.8420";"7.9770";"19.6414";"1.1000"
"267.0920";"8.0604";"19.7125";"1.1000"
"267.3420";"8.1439";"19.7778";"1.1000"
"267.5920";"8.2270";"19.8425";"1.1000"
"267.8420";"8.3104";"19.9055";"1.1000"
"268.0920";"8.3936";"19.9642";"1.1000"
"268.3420";"8.4771";"20.0285";"1.1000"
"268.5920";"8.5604";"20.0860";"1.1000"
"268.8420";"8.6438";"20.1448";"1.1000"
"269.0920";"8.7270";"20.2005";"1.1000"
"269.3420";"8.8104";"20.2551";"1.1000"
"269.5920";"8.8937";"20.3049";"1.1000"
"269.8420";"8.9770";"20.3572";"1.1000"
"270.0920";"9.0604";"20.4069";"1.1000"
"270.3420";"9.1438";"20.4544";"1.1000"
"270.5920";"9.2271";"20.4999";"1.1000"
"270.8420";"9.3104";"20.5443";"1.1000"
"271.0920";"9.3937";"20.5844";"1.1000"
"271.3420";"9.4770";"20.6282";"1.1000"
"271.5920";"9.5604";"20.6721";"1.1000"
"271.8420";"9.6438";"20.7139";"1.1000"
"272.0920";"9.7271";"20.7536";"1.1000"
"272.3420";"9.8104";"20.7957";"1.1000"
"272.5920";"9.8937";"20.8339";"1.1000"
"272.8420";"9.9770";"20.8728";"1.1000"
"273.0920";"10.0603";"20.9132";"1.1000"
"273.3420";"10.1439";"20.9498";"1.1000"
"273.5920";"10.2270";"20.9839";"1.1000"
"273.8420";"10.3104";"21.0185";"1.1000"
"274.0920";"10.3936";"21.0482";"1.1000"
"274.3420";"10.4770";"21.0814";"1.1000"
"274.5920";"10.5604";"21.1147";"1.1000"
"274.8420";"10.6438";"21.1454";"1.1000"
"275.0920";"10.7271";"21.1740";"1.1000"
"275.3420";"10.8103";"21.2020";"1.1000"
"275.5920";"10.8938";"21.2304";"1.1000"
"275.8420";"10.9771";"21.2582";"1.1000"
"276.0920";"11.0603";"21.2879";"1.1000"
"276.3420";"11.1437";"21.3174";"1.1000"
"276.5920";"11.2271";"21.3429";"1.1000"
"276.8420";"11.3104";"21.3684";"1.1000"
"277.0920";"11.3937";"21.3945";"1.1000"
"277.3420";"11.4770";"21.4202";"1.1000"
"277.5920";"11.5603";"21.4451";"1.1000"
"277.8420";"11.6438";"21.4696";"1.1000"
"278.0920";"11.7271";"21.4915";"1.1000"
"278.3420";"11.8103";"21.5144";"1.1000"
"278.5920";"11.8936";"21.5357";"1.1000"
"278.8420";"11.9770";"21.5573";"1.1000"
"279.0920";"12.0604";"21.5793";"1.1000"
"279.3420";"12.1439";"21.6007";"1.1000"
"279.5920";"12.2271";"21.6191";"1.1000"
"279.8420";"12.3103";"21.6375";"1.1000"
"280.0920";"12.3937";"21.6536";"1.1000"
"280.3420";"12.4770";"21.6753";"1.1000"
"280.5920";"12.5604";"21.6931";"1.1000"
"280.8420";"12.6437";"21.7096";"1.1000"
"281.0920";"12.7271";"21.7248";"1.1000"
"281.3420";"12.8104";"21.7419";"1.1000"
"281.5920";"12.8937";"21.7550";"1.1000"
"281.8420";"12.9770";"21.7730";"1.1000"
"282.0920";"13.0603";"21.7878";"1.1000"
"282.3420";"13.1437";"21.7995";"1.1000"
"282.5920";"13.2270";"21.8141";"1.1000"
"282.8420";"13.3105";"21.8273";"1.1000"
"283.0920";"13.3936";"21.8392";"1.1000"
"283.3420";"13.4770";"21.8524";"1.1000"
"283.5920";"13.5604";"21.8639";"1.1000"
"283.8420";"13.6439";"21.8760";"1.1000"
"284.0920";"13.7271";"21.8851";"1.1000"
"284.3420";"13.8103";"21.8964";"1.1000"
"284.5920";"13.8937";"21.9055";"1.1000"
"284.8420";"13.9769";"21.9148";"1.1000"
"285.0920";"14.0604";"21.9265";"1.1000"
"285.3420";"14.1438";"21.9364";"1.1000"
"285.5920";"14.2271";"21.9424";"1.1000"
"285.8420";"14.3103";"21.9512";"1.1000"
"286.0920";"14.3937";"21.9568";"1.1000"
"286.3420";"14.4770";"21.9654";"1.1000"
"286.5920";"14.5604";"21.9741";"1.1000"
"286.8420";"14.6438";"21.9806";"1.1000"
"287.0920";"14.7270";"21.9850";"1.1000"
"287.3420";"14.8103";"21.9910";"1.1000"
"287.5920";"14.8938";"21.9975";"1.1000"
"287.8420";"14.9770";"22.0038";"1.1000"
"288.0920";"15.0603";"22.0088";"1.1000"
"288.3420";"15.1438";"22.0119";"1.1000"
"288.5920";"15.2271";"22.0151";"1.1000"
"288.8420";"15.3104";"22.0196";"1.1000"
"289.0920";"15.3936";"22.0231";"1.1000"
"289.3420";"15.4770";"22.0271";"1.1000"
"289.5920";"15.5604";"22.0289";"1.1000"
"289.8420";"15.6438";"22.0327";"1.1000"
"290.0920";"15.7271";"22.0355";"1.1000"
"290.3420";"15.8103";"22.0372";"1.1000"
"290.5920";"15.8936";"22.0378";"1.1000"
"290.8420";"15.9770";"22.0399";"1.1000"
"291.0920";"16.0604";"22.0417";"1.1000"
"291.3420";"16.1438";"22.0437";"1.1000"
"291.5920";"16.2270";"22.0450";"1.1000"
"291.8420";"16.3104";"22.0436";"1.1000"
"292.0920";"16.3936";"22.0423";"1.1000"
"292.3420";"16.4770";"22.0436";"1.1000"
"292.5920";"16.5604";"22.0445";"1.1000"
"292.8420";"16.6438";"22.0428";"1.1000"
"293.0920";"16.7271";"22.0412";"1.1000"
"293.3420";"16.8103";"22.0394";"1.1000"
"293.5920";"16.8937";"22.0362";"1.1000"
"293.8420";"16.9770";"22.0355";"1.1000"
"294.0920";"17.0604";"22.0337";"1.1000"
"294.3420";"17.1437";"22.0312";"1.1000"
"294.5920";"17.2271";"22.0278";"1.1000"
"294.8420";"17.3105";"22.0238";"1.1000"
"295.0920";"17.3937";"22.0179";"1.1000"
"295.3420";"17.4769";"22.0154";"1.1000"
"295.5920";"17.5604";"22.0131";"1.1000"
"295.8420";"17.6439";"22.0073";"1.1000"
"296.0920";"17.7271";"22.0004";"1.1000"
"296.3420";"17.8103";"21.9958";"1.1000"
"296.5920";"17.8936";"21.9883";"1.1000"
"296.8420";"17.9770";"21.9828";"1.1000"
"297.0920";"18.0604";"21.9770";"1.1000"
"297.3420";"18.1438";"21.9684";"1.1000"
"297.5920";"18.2270";"21.9608";"1.1000"
"297.8420";"18.3104";"21.9526";"1.1000"
"298.0920";"18.3937";"21.9419";"1.1000"
"298.3420";"18.4770";"21.9335";"1.1000"
"298.5920";"18.5604";"21.9250";"1.1000"
"298.8420";"18.6438";"21.9147";"1.1000"
"299.0920";"18.7270";"21.9028";"1.1000"
"299.3420";"18.8104";"21.8909";"1.1000"
"299.5920";"18.8938";"21.8781";"1.1000"
"299.8420";"18.9770";"21.8646";"1.1000"
"300.0920";"19.0603";"21.8521";"1.1000"
"300.3420";"19.1438";"21.8383";"1.1000"
"300.5920";"19.2271";"21.8191";"1.1000"
"300.8420";"19.3104";"21.8017";"1.1000"
"301.0920";"19.3937";"21.7825";"1.1000"
"301.3420";"19.4770";"21.7639";"1.1000"
"301.5920";"19.5603";"21.7431";"1.1000"
"301.8420";"19.6438";"21.7203";"1.1000"
"302.0920";"19.7271";"21.6949";"1.1000"
"302.3420";"19.8104";"21.6673";"1.1000"
"302.5920";"19.8937";"21.6379";"1.1000"
"302.8420";"19.9771";"21.6073";"1.1000"
"303.0920";"20.0604";"21.5742";"1.1000"
"303.3420";"20.1438";"21.5374";"1.1000"
"303.5920";"20.2271";"21.4945";"1.1000"
"303.8420";"20.3104";"21.4488";"1.1000"
"304.0920";"20.3936";"21.3997";"1.1000"
"304.3420";"20.4771";"21.3494";"1.1000"
"304.5920";"20.5605";"21.2922";"1.1000"
"304.8420";"20.6438";"21.2281";"1.1000"
"305.0920";"20.7270";"21.1605";"1.1000"
"305.3420";"20.8103";"21.0876";"1.1000"
"305.5920";"20.8937";"21.0101";"1.1000"
"305.8420";"20.9770";"20.9299";"1.1000"
"306.0920";"21.0603";"20.8419";"1.1000"
"306.3420";"21.1438";"20.7483";"1.1000"
"306.5920";"21.2271";"20.6501";"1.1000"
"306.8420";"21.3105";"20.5459";"1.1000"
"307.0920";"21.3937";"20.4378";"1.1000"
"307.3420";"21.4769";"20.3262";"1.1000"
"307.5920";"21.5603";"20.2065";"1.1000"
"307.8420";"21.6438";"20.0797";"1.1000"
"308.0920";"21.7271";"19.9475";"1.1000"
"308.3420";"21.8103";"19.8120";"1.1000"
"308.5920";"21.8937";"19.6684";"1.1000"
"308.8420";"21.9770";"19.5180";"1.1000"
"309.0920";"22.0605";"19.3620";"1.1000"
"309.3420";"22.1439";"19.1967";"1.1000"
"309.5920";"22.2271";"19.0247";"1.1000"
"309.8420";"22.3103";"18.8478";"1.1000"
"310.0920";"22.3937";"18.6606";"1.1000"
"310.3420";"22.4771";"18.4672";"1.1000"
"310.5920";"22.5604";"18.2664";"1.1000"
"310.8420";"22.6438";"18.0523";"1.1000"
"311.0920";"22.7270";"17.8315";"1.1000"
"311.3420";"22.8104";"17.5996";"1.1000"
"311.5920";"22.8938";"17.3563";"1.1000"
"311.8420";"22.9770";"17.1031";"1.1000"
"312.0920";"23.0604";"16.8353";"1.1000"
"312.3420";"23.1438";"16.5516";"1.1000"
"312.5920";"23.2271";"16.2515";"1.1000"
"312.8420";"23.3104";"15.9307";"1.1000"
"313.0920";"23.3937";"15.5880";"1.1000"
"313.3420";"23.4770";"15.2024";"1.1000"
"313.4060";"23.4987";"9.1167";"1.1000"