File: data/c.csv
Time (s);Position (mm);Force (kN);Strain (%);
"0.0000";"0.0000";"0.0036";"0.0003"
"0.2500";"0.0031";"0.0176";"0.0004"
"0.5000";"0.0082";"0.0273";"0.0007"
"0.7500";"0.0124";"0.0337";"0.0009"
"1.0000";"0.0168";"0.0431";"0.0010"
"1.2500";"0.0210";"0.0619";"0.0011"
"1.5000";"0.0251";"0.0830";"0.0014"
"1.7500";"0.0291";"0.1029";"0.0019"
"2.0000";"0.0333";"0.1203";"0.0016"
"2.2500";"0.0376";"0.1354";"0.0020"
"2.5000";"0.0419";"0.1498";"0.0021"
"2.7500";"0.0459";"0.1631";"0.0022"
"3.0000";"0.0499";"0.1786";"0.0022"
"3.2500";"0.0541";"0.1943";"0.0022"
"3.5000";"0.0584";"0.2100";"0.0025"
"3.7500";"0.0627";"0.2255";"0.0024"
"4.0000";"0.0668";"0.2388";"0.0021"
"4.2500";"0.0709";"0.2519";"0.0023"
"4.5000";"0.0749";"0.2641";"0.0025"
"4.7500";"0.0791";"0.2787";"0.0024"
"5.0000";"0.0834";"0.2936";"0.0030"
"5.2500";"0.0877";"0.3090";"0.0026"
"5.5000";"0.0918";"0.3235";"0.0029"
"5.7500";"0.0958";"0.3366";"0.0029"
"6.0000";"0.0999";"0.3498";"0.0031"
"6.2500";"0.1042";"0.3629";"0.0030"
"6.5000";"0.1085";"0.3771";"0.0033"
"6.7500";"0.1127";"0.3898";"0.0035"
"7.0000";"0.1167";"0.4020";"0.0036"
"7.2500";"0.1208";"0.4142";"0.0038"
"7.5000";"0.1251";"0.4276";"0.0040"
"7.7500";"0.1294";"0.4423";"0.0041"
"8.0000";"0.1335";"0.4559";"0.0045"
"8.2500";"0.1375";"0.4685";"0.0046"
"8.5000";"0.1416";"0.4816";"0.0047"
"8.7500";"0.1457";"0.4946";"0.0048"
"9.0000";"0.1502";"0.5112";"0.0050"
"9.2500";"0.1544";"0.5261";"0.0052"
"9.5000";"0.1585";"0.5386";"0.0055"
"9.7500";"0.1624";"0.5489";"0.0055"
"10.0000";"0.1665";"0.5606";"0.0055"
"10.2500";"0.1709";"0.5750";"0.0058"
"10.5000";"0.1752";"0.5900";"0.0058"
"10.7500";"0.1793";"0.6028";"0.0061"
"11.0000";"0.1834";"0.6141";"0.0059"
"11.2500";"0.1875";"0.6254";"0.0061"
"11.5000";"0.1916";"0.6371";"0.0061"
"11.7500";"0.1960";"0.6519";"0.0064"
"12.0000";"0.2001";"0.6662";"0.0067"
"12.2500";"0.2042";"0.6778";"0.0067"
"12.5000";"0.2082";"0.6893";"0.0065"
"12.7500";"0.2125";"0.7021";"0.0065"
"13.0000";"0.2169";"0.7172";"0.0066"
"13.2500";"0.2211";"0.7327";"0.0067"
"13.5000";"0.2251";"0.7443";"0.0065"
"13.7500";"0.2291";"0.7550";"0.0064"
"14.0000";"0.2333";"0.7674";"0.0065"
"14.2500";"0.2375";"0.7821";"0.0063"
"14.5000";"0.2419";"0.8003";"0.0066"
"14.7500";"0.2460";"0.8146";"0.0064"
"15.0000";"0.2500";"0.8254";"0.0063"
"15.2500";"0.2540";"0.8380";"0.0065"
"15.5000";"0.2583";"0.8526";"0.0067"
"15.7500";"0.2626";"0.8695";"0.0066"
"16.0000";"0.2668";"0.8867";"0.0067"
"16.2500";"0.2709";"0.9008";"0.0069"
"16.5000";"0.2750";"0.9143";"0.0069"
"16.7500";"0.2792";"0.9286";"0.0074"
"17.0000";"0.2834";"0.9444";"0.0072"
"17.2500";"0.2877";"0.9630";"0.0073"
"17.5000";"0.2917";"0.9781";"0.0075"
"17.7500";"0.2958";"0.9916";"0.0075"
"18.0000";"0.2999";"1.0053";"0.0074"
"18.2500";"0.3042";"1.0234";"0.0078"
"18.5000";"0.3086";"1.0438";"0.0080"
"18.7500";"0.3127";"1.0616";"0.0081"
"19.0000";"0.3167";"1.0758";"0.0081"
"19.2500";"0.3207";"1.0902";"0.0083"
"19.5000";"0.3249";"1.1066";"0.0085"
"19.7500";"0.3293";"1.1268";"0.0086"
"20.0000";"0.3336";"1.1492";"0.0088"
"20.2500";"0.3376";"1.1652";"0.0088"
"20.5000";"0.3416";"1.1794";"0.0089"
"20.7500";"0.3458";"1.1949";"0.0090"
"21.0000";"0.3501";"1.2156";"0.0091"
"21.2500";"0.3544";"1.2379";"0.0095"
"21.5000";"0.3584";"1.2561";"0.0096"
"21.7500";"0.3625";"1.2718";"0.0097"
"22.0000";"0.3666";"1.2872";"0.0097"
"22.2500";"0.3709";"1.3078";"0.0099"
"22.5000";"0.3752";"1.3321";"0.0103"
"22.7500";"0.3793";"1.3526";"0.0106"
"23.0000";"0.3833";"1.3691";"0.0106"
"23.2500";"0.3874";"1.3850";"0.0106"
"23.5000";"0.3916";"1.4043";"0.0110"
"23.7500";"0.3960";"1.4278";"0.0111"
"24.0000";"0.4003";"1.4502";"0.0112"
"24.2500";"0.4043";"1.4666";"0.0114"
"24.5000";"0.4083";"1.4821";"0.0117"
"24.7500";"0.4124";"1.4994";"0.0119"
"25.0000";"0.4167";"1.5206";"0.0120"
"25.2500";"0.4210";"1.5449";"0.0123"
"25.5000";"0.4252";"1.5647";"0.0124"
"25.7500";"0.4292";"1.5798";"0.0127"
"26.0000";"0.4333";"1.5965";"0.0129"
"26.2500";"0.4375";"1.6155";"0.0132"
"26.5000";"0.4418";"1.6384";"0.0132"
"26.7500";"0.4460";"1.6605";"0.0133"
"27.0000";"0.4500";"1.6782";"0.0135"
"27.2500";"0.4541";"1.6934";"0.0138"
"27.5000";"0.4583";"1.7115";"0.0139"
"27.7500";"0.4627";"1.7340";"0.0142"
"28.0000";"0.4669";"1.7572";"0.0144"
"28.2500";"0.4710";"1.7760";"0.0145"
"28.5000";"0.4750";"1.7925";"0.0147"
"28.7500";"0.4790";"1.8086";"0.0148"
"29.0000";"0.4833";"1.8288";"0.0151"
"29.2500";"0.4877";"1.8534";"0.0152"
"29.5000";"0.4919";"1.8741";"0.0155"
"29.7500";"0.4959";"1.8894";"0.0158"
"30.0000";"0.4999";"1.9061";"0.0160"
"30.2500";"0.5041";"1.9255";"0.0162"
"30.5000";"0.5085";"1.9486";"0.0163"
"30.7500";"0.5127";"1.9730";"0.0165"
"31.0000";"0.5167";"1.9910";"0.0165"
"31.2500";"0.5208";"2.0061";"0.0168"
"31.5000";"0.5249";"2.0236";"0.0169"
"31.7500";"0.5293";"2.0473";"0.0170"
"32.0000";"0.5336";"2.0718";"0.0173"
"32.2500";"0.5376";"2.0918";"0.0175"
"32.5000";"0.5416";"2.1074";"0.0178"
"32.7500";"0.5457";"2.1245";"0.0180"
"33.0000";"0.5501";"2.1462";"0.0181"
"33.2500";"0.5544";"2.1719";"0.0182"
"33.5000";"0.5586";"2.1942";"0.0185"
"33.7500";"0.5625";"2.2109";"0.0189"
"34.0000";"0.5666";"2.2271";"0.0189"
"34.2500";"0.5708";"2.2459";"0.0191"
"34.5000";"0.5751";"2.2714";"0.0194"
"34.7500";"0.5793";"2.2960";"0.0196"
"35.0000";"0.5834";"2.3149";"0.0197"
"35.2500";"0.5875";"2.3315";"0.0198"
"35.5000";"0.5916";"2.3495";"0.0201"
"35.7500";"0.5959";"2.3721";"0.0202"
"36.0000";"0.6002";"2.3979";"0.0203"
"36.2500";"0.6043";"2.4193";"0.0207"
"36.5000";"0.6083";"2.4356";"0.0207"
"36.7500";"0.6124";"2.4543";"0.0210"
"37.0000";"0.6167";"2.4763";"0.0212"
"37.2500";"0.6211";"2.5025";"0.0213"
"37.5000";"0.6252";"2.5247";"0.0215"
"37.7500";"0.6292";"2.5425";"0.0219"
"38.0000";"0.6332";"2.5587";"0.0220"
"38.2500";"0.6374";"2.5797";"0.0221"
"38.5000";"0.6418";"2.6044";"0.0224"
"38.7500";"0.6461";"2.6309";"0.0225"
"39.0000";"0.6502";"2.6508";"0.0227"
"39.2500";"0.6541";"2.6664";"0.0228"
"39.5000";"0.6582";"2.6844";"0.0229"
"39.7500";"0.6625";"2.7079";"0.0230"
"40.0000";"0.6668";"2.7345";"0.0233"
"40.2500";"0.6709";"2.7582";"0.0236"
"40.5000";"0.6750";"2.7763";"0.0238"
"40.7500";"0.6791";"2.7932";"0.0240"
"41.0000";"0.6834";"2.8145";"0.0242"
"41.2500";"0.6877";"2.8395";"0.0244"
"41.5000";"0.6918";"2.8655";"0.0248"
"41.7500";"0.6959";"2.8850";"0.0249"
"42.0000";"0.6999";"2.9028";"0.0249"
"42.2500";"0.7040";"2.9215";"0.0249"
"42.5000";"0.7085";"2.9485";"0.0253"
"42.7500";"0.7128";"2.9740";"0.0255"
"43.0000";"0.7168";"2.9946";"0.0256"
"43.2500";"0.7208";"3.0113";"0.0259"
"43.5000";"0.7249";"3.0310";"0.0259"
"43.7500";"0.7292";"3.0539";"0.0261"
"44.0000";"0.7336";"3.0833";"0.0264"
"44.2500";"0.7377";"3.1072";"0.0266"
"44.5000";"0.7417";"3.1238";"0.0266"
"44.7500";"0.7458";"3.1421";"0.0270"
"45.0000";"0.7500";"3.1638";"0.0271"
"45.2500";"0.7543";"3.1922";"0.0275"
"45.5000";"0.7585";"3.2163";"0.0275"
"45.7500";"0.7625";"3.2366";"0.0278"
"46.0000";"0.7666";"3.2548";"0.0278"
"46.2500";"0.7708";"3.2768";"0.0281"
"46.5000";"0.7752";"3.3026";"0.0282"
"46.7500";"0.7794";"3.3299";"0.0284"
"47.0000";"0.7834";"3.3507";"0.0287"
"47.2500";"0.7874";"3.3691";"0.0287"
"47.5000";"0.7916";"3.3897";"0.0289"
"47.7500";"0.7959";"3.4122";"0.0291"
"48.0000";"0.8002";"3.4408";"0.0293"
"48.2500";"0.8044";"3.4656";"0.0295"
"48.5000";"0.8084";"3.4849";"0.0297"
"48.7500";"0.8124";"3.5024";"0.0298"
"49.0000";"0.8166";"3.5256";"0.0303"
"49.2500";"0.8209";"3.5504";"0.0304"
"49.5000";"0.8252";"3.5789";"0.0306"
"49.7500";"0.8292";"3.6014";"0.0307"
"50.0000";"0.8333";"3.6198";"0.0309"
"50.2500";"0.8375";"3.6405";"0.0312"
"50.5000";"0.8418";"3.6652";"0.0313"
"50.7500";"0.8461";"3.6928";"0.0313"
"51.0000";"0.8501";"3.7171";"0.0318"
"51.2500";"0.8542";"3.7376";"0.0317"
"51.5000";"0.8583";"3.7574";"0.0321"
"51.7500";"0.8625";"3.7814";"0.0320"
"52.0000";"0.8669";"3.8095";"0.0322"
"52.2500";"0.8710";"3.8362";"0.0327"
"52.5000";"0.8750";"3.8550";"0.0328"
"52.7500";"0.8791";"3.8750";"0.0328"
"53.0000";"0.8832";"3.8967";"0.0332"
"53.2500";"0.8876";"3.9237";"0.0334"
"53.5000";"0.8919";"3.9535";"0.0336"
"53.7500";"0.8959";"3.9761";"0.0336"
"54.0000";"0.9000";"3.9940";"0.0338"
"54.2500";"0.9041";"4.0139";"0.0340"
"54.5000";"0.9084";"4.0392";"0.0342"
"54.7500";"0.9127";"4.0693";"0.0344"
"55.0000";"0.9168";"4.0951";"0.0346"
"55.2500";"0.9208";"4.1135";"0.0348"
"55.5000";"0.9249";"4.1330";"0.0350"
"55.7500";"0.9292";"4.1565";"0.0354"
"56.0000";"0.9336";"4.1868";"0.0356"
"56.2500";"0.9377";"4.2123";"0.0357"
"56.5000";"0.9417";"4.2324";"0.0358"
"56.7500";"0.9457";"4.2513";"0.0360"
"57.0000";"0.9499";"4.2733";"0.0360"
"57.2500";"0.9544";"4.3023";"0.0364"
"57.5000";"0.9585";"4.3300";"0.0367"
"57.7500";"0.9626";"4.3527";"0.0367"
"58.0000";"0.9666";"4.3703";"0.0368"
"58.2500";"0.9707";"4.3915";"0.0373"
"58.5000";"0.9750";"4.4154";"0.0374"
"58.7500";"0.9793";"4.4458";"0.0375"
"59.0000";"0.9835";"4.4720";"0.0377"
"59.2500";"0.9876";"4.4938";"0.0380"
"59.5000";"0.9916";"4.5120";"0.0381"
"59.7500";"0.9958";"4.5350";"0.0383"
"60.0000";"1.0001";"4.5613";"0.0385"
"60.2500";"1.0044";"4.5900";"0.0388"
"60.5000";"1.0084";"4.6133";"0.0390"
"60.7500";"1.0124";"4.6320";"0.0391"
"61.0000";"1.0167";"4.6545";"0.0391"
"61.2500";"1.0210";"4.6801";"0.0394"
"61.5000";"1.0252";"4.7096";"0.0396"
"61.7500";"1.0293";"4.7321";"0.0397"
"62.0000";"1.0333";"4.7534";"0.0399"
"62.2500";"1.0373";"4.7718";"0.0402"
"62.5000";"1.0417";"4.7976";"0.0402"
"62.7500";"1.0460";"4.8262";"0.0407"
"63.0000";"1.0502";"4.8538";"0.0407"
"63.2500";"1.0542";"4.8737";"0.0409"
"63.5000";"1.0583";"4.8936";"0.0412"
"63.7500";"1.0625";"4.9145";"0.0414"
"64.0000";"1.0668";"4.9421";"0.0417"
"64.2500";"1.0710";"4.9726";"0.0418"
"64.5000";"1.0750";"4.9947";"0.0419"
"64.7500";"1.0792";"5.0154";"0.0422"
"65.0000";"1.0833";"5.0357";"0.0424"
"65.2500";"1.0876";"5.0630";"0.0428"
"65.5000";"1.0919";"5.0909";"0.0427"
"65.7500";"1.0960";"5.1170";"0.0429"
"66.0000";"1.0999";"5.1351";"0.0432"
"66.2500";"1.1040";"5.1560";"0.0433"
"66.5000";"1.1084";"5.1805";"0.0434"
"66.7500";"1.1128";"5.2122";"0.0439"
"67.0000";"1.1169";"5.2389";"0.0440"
"67.2500";"1.1209";"5.2582";"0.0440"
"67.5000";"1.1249";"5.2776";"0.0443"
"67.7500";"1.1291";"5.2995";"0.0443"
"68.0000";"1.1335";"5.3308";"0.0448"
"68.2500";"1.1377";"5.3596";"0.0453"
"68.5000";"1.1418";"5.3824";"0.0453"
"68.7500";"1.1458";"5.4023";"0.0453"
"69.0000";"1.1500";"5.4250";"0.0456"
"69.2500";"1.1543";"5.4509";"0.0458"
"69.5000";"1.1585";"5.4813";"0.0459"
"69.7500";"1.1626";"5.5070";"0.0464"
"70.0000";"1.1666";"5.5274";"0.0464"
"70.2500";"1.1708";"5.5501";"0.0465"
"70.5000";"1.1751";"5.5746";"0.0468"
"70.7500";"1.1794";"5.6046";"0.0471"
"71.0000";"1.1835";"5.6318";"0.0474"
"71.2500";"1.1876";"5.6546";"0.0473"
"71.5000";"1.1916";"5.6739";"0.0474"
"71.7500";"1.1957";"5.6989";"0.0477"
"72.0000";"1.2001";"5.7265";"0.0480"
"72.2500";"1.2044";"5.7587";"0.0482"
"72.5000";"1.2085";"5.7823";"0.0484"
"72.7500";"1.2125";"5.8016";"0.0488"
"73.0000";"1.2166";"5.8236";"0.0487"
"73.2500";"1.2208";"5.8496";"0.0490"
"73.5000";"1.2252";"5.8807";"0.0493"
"73.7500";"1.2293";"5.9089";"0.0497"
"74.0000";"1.2334";"5.9315";"0.0497"
"74.2500";"1.2374";"5.9515";"0.0497"
"74.5000";"1.2418";"5.9776";"0.0500"
"74.7500";"1.2460";"6.0064";"0.0504"
"75.0000";"1.2502";"6.0352";"0.0505"
"75.2500";"1.2542";"6.0581";"0.0507"
"75.5000";"1.2582";"6.0796";"0.0509"
"75.7500";"1.2624";"6.1024";"0.0511"
"76.0000";"1.2668";"6.1316";"0.0513"
"76.2500";"1.2711";"6.1616";"0.0517"
"76.5000";"1.2751";"6.1865";"0.0518"
"76.7500";"1.2791";"6.2069";"0.0518"
"77.0000";"1.2832";"6.2281";"0.0521"
"77.2500";"1.2875";"6.2550";"0.0523"
"77.5000";"1.2919";"6.2868";"0.0523"
"77.7500";"1.2960";"6.3166";"0.0527"
"78.0000";"1.3001";"6.3369";"0.0531"
"78.2500";"1.3041";"6.3581";"0.0530"
"78.5000";"1.3083";"6.3820";"0.0534"
"78.7500";"1.3127";"6.4128";"0.0534"
"79.0000";"1.3168";"6.4429";"0.0539"
"79.2500";"1.3209";"6.4671";"0.0541"
"79.5000";"1.3249";"6.4884";"0.0542"
"79.7500";"1.3292";"6.5131";"0.0544"
"80.0000";"1.3335";"6.5413";"0.0547"
"80.2500";"1.3378";"6.5726";"0.0551"
"80.5000";"1.3418";"6.5963";"0.0552"
"80.7500";"1.3458";"6.6172";"0.0553"
"81.0000";"1.3499";"6.6420";"0.0556"
"81.2500";"1.3542";"6.6683";"0.0557"
"81.5000";"1.3585";"6.7003";"0.0560"
"81.7500";"1.3627";"6.7291";"0.0563"
"82.0000";"1.3667";"6.7509";"0.0564"
"82.2500";"1.3707";"6.7720";"0.0564"
"82.5000";"1.3750";"6.7970";"0.0568"
"82.7500";"1.3792";"6.8244";"0.0571"
"83.0000";"1.3835";"6.8575";"0.0573"
"83.2500";"1.3876";"6.8840";"0.0576"
"83.5000";"1.3916";"6.9052";"0.0577"
"83.7500";"1.3958";"6.9288";"0.0580"
"84.0000";"1.4001";"6.9557";"0.0582"
"84.2500";"1.4043";"6.9864";"0.0582"
"84.5000";"1.4084";"7.0148";"0.0587"
"84.7500";"1.4125";"7.0380";"0.0588"
"85.0000";"1.4165";"7.0605";"0.0590"
"85.2500";"1.4209";"7.0870";"0.0590"
"85.5000";"1.4252";"7.1193";"0.0592"
"85.7500";"1.4294";"7.1484";"0.0597"
"86.0000";"1.4334";"7.1714";"0.0601"
"86.2500";"1.4374";"7.1929";"0.0600"
"86.5000";"1.4416";"7.2169";"0.0603"
"86.7500";"1.4460";"7.2477";"0.0606"
"87.0000";"1.4502";"7.2802";"0.0607"
"87.2500";"1.4543";"7.3060";"0.0607"
"87.5000";"1.4583";"7.3275";"0.0609"
"87.7500";"1.4625";"7.3494";"0.0613"
"88.0000";"1.4667";"7.3770";"0.0614"
"88.2500";"1.4710";"7.4101";"0.0618"
"88.5000";"1.4751";"7.4397";"0.0620"
"88.7500";"1.4792";"7.4617";"0.0623"
"89.0000";"1.4833";"7.4848";"0.0624"
"89.2500";"1.4875";"7.5107";"0.0628"
"89.5000";"1.4919";"7.5431";"0.0629"
"89.7500";"1.4960";"7.5725";"0.0631"
"90.0000";"1.5000";"7.5958";"0.0635"
"90.2500";"1.5040";"7.6179";"0.0635"
"90.5000";"1.5082";"7.6427";"0.0640"
"90.7500";"1.5127";"7.6744";"0.0638"
"91.0000";"1.5169";"7.7074";"0.0644"
"91.2500";"1.5210";"7.7327";"0.0645"
"91.5000";"1.5250";"7.7539";"0.0648"
"91.7500";"1.5291";"7.7770";"0.0650"
"92.0000";"1.5334";"7.8045";"0.0651"
"92.2500";"1.5377";"7.8367";"0.0654"
"92.5000";"1.5418";"7.8665";"0.0657"
"92.7500";"1.5458";"7.8904";"0.0658"
"93.0000";"1.5500";"7.9130";"0.0660"
"93.2500";"1.5542";"7.9377";"0.0660"
"93.5000";"1.5585";"7.9678";"0.0662"
"93.7500";"1.5626";"7.9992";"0.0667"
"94.0000";"1.5667";"8.0270";"0.0667"
"94.2500";"1.5708";"8.0483";"0.0671"
"94.5000";"1.5750";"8.0739";"0.0672"
"94.7500";"1.5793";"8.1021";"0.0676"
"95.0000";"1.5836";"8.1355";"0.0677"
"95.2500";"1.5876";"8.1619";"0.0679"
"95.5000";"1.5917";"8.1856";"0.0683"
"95.7500";"1.5957";"8.2066";"0.0683"
"96.0000";"1.6000";"8.2347";"0.0686"
"96.2500";"1.6044";"8.2674";"0.0689"
"96.5000";"1.6086";"8.3001";"0.0690"
"96.7500";"1.6125";"8.3233";"0.0693"
"97.0000";"1.6166";"8.3448";"0.0697"
"97.2500";"1.6208";"8.3685";"0.0701"
"97.5000";"1.6252";"8.4000";"0.0701"
"97.7500";"1.6293";"8.4342";"0.0702"
"98.0000";"1.6334";"8.4607";"0.0706"
"98.2500";"1.6375";"8.4834";"0.0707"
"98.5000";"1.6416";"8.5061";"0.0711"
"98.7500";"1.6460";"8.5354";"0.0714"
"99.0000";"1.6502";"8.5676";"0.0713"
"99.2500";"1.6543";"8.5975";"0.0716"
"99.5000";"1.6583";"8.6188";"0.0717"
"99.7500";"1.6624";"8.6411";"0.0721"
"100.0000";"1.6667";"8.6678";"0.0722"
"100.2500";"1.6711";"8.7021";"0.0722"
"100.5000";"1.6752";"8.7336";"0.0726"
"100.7500";"1.6792";"8.7560";"0.0729"
"101.0000";"1.6833";"8.7771";"0.0729"
"101.2500";"1.6874";"8.8004";"0.0732"
"101.5000";"1.6918";"8.8345";"0.0735"
"101.7500";"1.6960";"8.8684";"0.0739"
"102.0000";"1.7001";"8.8960";"0.0740"
"102.2500";"1.7041";"8.9167";"0.0741"
"102.5000";"1.7083";"8.9407";"0.0743"
"102.7500";"1.7126";"8.9683";"0.0748"
"103.0000";"1.7169";"9.0042";"0.0750"
"103.2500";"1.7210";"9.0319";"0.0752"
"103.5000";"1.7250";"9.0554";"0.0756"
"103.7500";"1.7291";"9.0786";"0.0756"
"104.0000";"1.7334";"9.1062";"0.0757"
"104.2500";"1.7378";"9.1406";"0.0760"
"104.5000";"1.7418";"9.1704";"0.0764"
"104.7500";"1.7459";"9.1954";"0.0766"
"105.0000";"1.7499";"9.2164";"0.0768"
"105.2500";"1.7541";"9.2438";"0.0770"
"105.5000";"1.7584";"9.2734";"0.0773"
"105.7500";"1.7627";"9.3091";"0.0778"
"106.0000";"1.7668";"9.3355";"0.0778"
"106.2500";"1.7708";"9.3575";"0.0780"
"106.5000";"1.7749";"9.3786";"0.0782"
"106.7500";"1.7792";"9.4080";"0.0784"
"107.0000";"1.7835";"9.4403";"0.0788"
"107.2500";"1.7876";"9.4733";"0.0789"
"107.5000";"1.7917";"9.4972";"0.0792"
"107.7500";"1.7958";"9.5187";"0.0794"
"108.0000";"1.8001";"9.5455";"0.0797"
"108.2500";"1.8044";"9.5774";"0.0799"
"108.5000";"1.8085";"9.6094";"0.0800"
"108.7500";"1.8125";"9.6341";"0.0802"
"109.0000";"1.8166";"9.6584";"0.0805"
"109.2500";"1.8207";"9.6821";"0.0807"
"109.5000";"1.8252";"9.7161";"0.0808"
"109.7500";"1.8294";"9.7478";"0.0812"
"110.0000";"1.8334";"9.7756";"0.0812"
"110.2500";"1.8374";"9.7961";"0.0817"
"110.5000";"1.8416";"9.8199";"0.0818"
"110.7500";"1.8459";"9.8484";"0.0820"
"111.0000";"1.8502";"9.8836";"0.0822"
"111.2500";"1.8543";"9.9152";"0.0826"
"111.5000";"1.8584";"9.9388";"0.0827"
"111.7500";"1.8625";"9.9621";"0.0831"
"112.0000";"1.8666";"9.9861";"0.0831"
"112.2500";"1.8710";"10.0192";"0.0832"
"112.5000";"1.8751";"10.0505";"0.0836"
"112.7500";"1.8792";"10.0795";"0.0838"
"113.0000";"1.8832";"10.1003";"0.0842"
"113.2500";"1.8875";"10.1262";"0.0843"
"113.5000";"1.8918";"10.1562";"0.0846"
"113.7500";"1.8961";"10.1915";"0.0848"
"114.0000";"1.9001";"10.2175";"0.0852"
"114.2500";"1.9041";"10.2401";"0.0852"
"114.5000";"1.9083";"10.2642";"0.0854"
"114.7500";"1.9125";"10.2917";"0.0859"
"115.0000";"1.9169";"10.3274";"0.0859"
"115.2500";"1.9210";"10.3577";"0.0861"
"115.5000";"1.9251";"10.3815";"0.0864"
"115.7500";"1.9291";"10.4032";"0.0866"
"116.0000";"1.9333";"10.4306";"0.0869"
"116.2500";"1.9376";"10.4595";"0.0870"
"116.5000";"1.9418";"10.4946";"0.0874"
"116.7500";"1.9459";"10.5227";"0.0876"
"117.0000";"1.9500";"10.5464";"0.0879"
"117.2500";"1.9542";"10.5707";"0.0882"
"117.5000";"1.9584";"10.5995";"0.0883"
"117.7500";"1.9627";"10.6329";"0.0886"
"118.0000";"1.9668";"10.6630";"0.0888"
"118.2500";"1.9709";"10.6890";"0.0887"
"118.5000";"1.9749";"10.7114";"0.0894"
"118.7500";"1.9792";"10.7411";"0.0896"
"119.0000";"1.9835";"10.7722";"0.0897"
"119.2500";"1.9877";"10.8046";"0.0900"
"119.5000";"1.9917";"10.8278";"0.0902"
"119.7500";"1.9958";"10.8533";"0.0904"
"120.0000";"1.9999";"10.8761";"0.0907"
"120.2500";"2.0043";"10.9081";"0.0909"
"120.5000";"2.0086";"10.9425";"0.0913"
"120.7500";"2.0126";"10.9701";"0.0913"
"121.0000";"2.0166";"10.9922";"0.0915"
"121.2500";"2.0208";"11.0151";"0.0918"
"121.5000";"2.0250";"11.0441";"0.0919"
"121.7500";"2.0293";"11.0784";"0.0923"
"122.0000";"2.0334";"11.1109";"0.0926"
"122.2500";"2.0375";"11.1344";"0.0927"
"122.5000";"2.0416";"11.1588";"0.0928"
"122.7500";"2.0459";"11.1837";"0.0932"
"123.0000";"2.0502";"11.2167";"0.0935"
"123.2500";"2.0543";"11.2482";"0.0937"
"123.5000";"2.0583";"11.2735";"0.0938"
"123.7500";"2.0624";"11.2959";"0.0940"
"124.0000";"2.0666";"11.3195";"0.0943"
"124.2500";"2.0710";"11.3533";"0.0946"
"124.5000";"2.0752";"11.3878";"0.0948"
"124.7500";"2.0793";"11.4152";"0.0950"
"125.0000";"2.0833";"11.4352";"0.0954"
"125.2500";"2.0874";"11.4593";"0.0954"
"125.5000";"2.0917";"11.4876";"0.0956"
"125.7500";"2.0960";"11.5231";"0.0960"
"126.0000";"2.1002";"11.5538";"0.0962"
"126.2500";"2.1042";"11.5782";"0.0965"
"126.5000";"2.1083";"11.6009";"0.0968"
"126.7500";"2.1125";"11.6261";"0.0969"
"127.0000";"2.1169";"11.6583";"0.0972"
"127.2500";"2.1210";"11.6902";"0.0974"
"127.5000";"2.1250";"11.7185";"0.0975"
"127.7500";"2.1291";"11.7405";"0.0979"
"128.0000";"2.1333";"11.7672";"0.0980"
"128.2500";"2.1376";"11.7965";"0.0985"
"128.5000";"2.1419";"11.8304";"0.0985"
"128.7500";"2.1459";"11.8587";"0.0989"
"129.0000";"2.1500";"11.8837";"0.0989"
"129.2500";"2.1540";"11.9051";"0.0993"
"129.5000";"2.1583";"11.9336";"0.0995"
"129.7500";"2.1627";"11.9686";"0.0997"
"130.0000";"2.1669";"12.0019";"0.0999"
"130.2500";"2.1709";"12.0262";"0.1003"
"130.5000";"2.1750";"12.0479";"0.1005"
"130.7500";"2.1791";"12.0715";"0.1007"
"131.0000";"2.1834";"12.1040";"0.1007"
"131.2500";"2.1877";"12.1407";"0.1013"
"131.5000";"2.1917";"12.1682";"0.1015"
"131.7500";"2.1958";"12.1923";"0.1015"
"132.0000";"2.1999";"12.2160";"0.1018"
"132.2500";"2.2043";"12.2472";"0.1023"
"132.5000";"2.2086";"12.2807";"0.1022"
"132.7500";"2.2126";"12.3104";"0.1028"
"133.0000";"2.2166";"12.3322";"0.1028"
"133.2500";"2.2207";"12.3572";"0.1030"
"133.5000";"2.2250";"12.3849";"0.1032"
"133.7500";"2.2294";"12.4217";"0.1036"
"134.0000";"2.2335";"12.4533";"0.1037"
"134.2500";"2.2375";"12.4775";"0.1040"
"134.5000";"2.2416";"12.4995";"0.1042"
"134.7500";"2.2457";"12.5250";"0.1043"
"135.0000";"2.2501";"12.5579";"0.1048"
"135.2500";"2.2543";"12.5935";"0.1050"
"135.5000";"2.2584";"12.6230";"0.1055"
"135.7500";"2.2625";"12.6451";"0.1053"
"136.0000";"2.2666";"12.6697";"0.1056"
"136.2500";"2.2709";"12.6983";"0.1060"
"136.5000";"2.2752";"12.7346";"0.1060"
"136.7500";"2.2792";"12.7642";"0.1066"
"137.0000";"2.2833";"12.7892";"0.1066"
"137.2500";"2.2874";"12.8128";"0.1068"
"137.5000";"2.2917";"12.8431";"0.1071"
"137.7500";"2.2960";"12.8772";"0.1074"
"138.0000";"2.3002";"12.9085";"0.1077"
"138.2500";"2.3042";"12.9330";"0.1076"
"138.5000";"2.3082";"12.9573";"0.1080"
"138.7500";"2.3124";"12.9839";"0.1081"
"139.0000";"2.3168";"13.0158";"0.1086"
"139.2500";"2.3211";"13.0522";"0.1090"
"139.5000";"2.3252";"13.0787";"0.1091"
"139.7500";"2.3291";"13.1027";"0.1093"
"140.0000";"2.3333";"13.1249";"0.1094"
"140.2500";"2.3375";"13.1539";"0.1097"
"140.5000";"2.3418";"13.1872";"0.1099"
"140.7500";"2.3460";"13.2227";"0.1101"
"141.0000";"2.3500";"13.2473";"0.1106"
"141.2500";"2.3542";"13.2718";"0.1108"
"141.5000";"2.3583";"13.2979";"0.1109"
"141.7500";"2.3627";"13.3311";"0.1112"
"142.0000";"2.3668";"13.3642";"0.1115"
"142.2500";"2.3709";"13.3927";"0.1117"
"142.5000";"2.3749";"13.4168";"0.1120"
"142.7500";"2.3791";"13.4410";"0.1122"
"143.0000";"2.3835";"13.4748";"0.1125"
"143.2500";"2.3878";"13.5095";"0.1127"
"143.5000";"2.3918";"13.5397";"0.1129"
"143.7500";"2.3957";"13.5604";"0.1134"
"144.0000";"2.3999";"13.5862";"0.1134"
"144.2500";"2.4042";"13.6142";"0.1139"
"144.5000";"2.4086";"13.6533";"0.1139"
"144.7500";"2.4127";"13.6863";"0.1142"
"145.0000";"2.4167";"13.7105";"0.1144"
"145.2500";"2.4208";"13.7336";"0.1148"
"145.5000";"2.4250";"13.7591";"0.1147"
"145.7500";"2.4293";"13.7938";"0.1155"
"146.0000";"2.4335";"13.8262";"0.1153"
"146.2500";"2.4375";"13.8547";"0.1157"
"146.5000";"2.4416";"13.8787";"0.1160"
"146.7500";"2.4458";"13.9075";"0.1160"
"147.0000";"2.4501";"13.9377";"0.1165"
"147.2500";"2.4544";"13.9746";"0.1169"
"147.5000";"2.4584";"14.0024";"0.1166"
"147.7500";"2.4625";"14.0281";"0.1172"
"148.0000";"2.4666";"14.0540";"0.1175"
"148.2500";"2.4708";"14.0828";"0.1176"
"148.5000";"2.4752";"14.1187";"0.1180"
"148.7500";"2.4794";"14.1530";"0.1183"
"149.0000";"2.4834";"14.1784";"0.1185"
"149.2500";"2.4874";"14.2004";"0.1187"
"149.5000";"2.4916";"14.2292";"0.1189"
"149.7500";"2.4959";"14.2607";"0.1192"
"150.0000";"2.5002";"14.2985";"0.1194"
"150.2500";"2.5042";"14.3268";"0.1197"
"150.5000";"2.5083";"14.3516";"0.1201"
"150.7500";"2.5125";"14.3788";"0.1199"
"151.0000";"2.5168";"14.4094";"0.1204"
"151.2500";"2.5210";"14.4420";"0.1209"
"151.5000";"2.5251";"14.4738";"0.1212"
"151.7500";"2.5291";"14.5002";"0.1211"
"152.0000";"2.5332";"14.5260";"0.1216"
"152.2500";"2.5376";"14.5571";"0.1217"
"152.5000";"2.5419";"14.5896";"0.1219"
"152.7500";"2.5460";"14.6247";"0.1225"
"153.0000";"2.5500";"14.6509";"0.1224"
"153.2500";"2.5541";"14.6757";"0.1227"
"153.5000";"2.5582";"14.6996";"0.1231"
"153.7500";"2.5626";"14.7339";"0.1234"
"154.0000";"2.5668";"14.7713";"0.1236"
"154.2500";"2.5710";"14.8032";"0.1238"
"154.5000";"2.5750";"14.8256";"0.1240"
"154.7500";"2.5790";"14.8494";"0.1242"
"155.0000";"2.5833";"14.8795";"0.1244"
"155.2500";"2.5877";"14.9170";"0.1250"
"155.5000";"2.5918";"14.9517";"0.1252"
"155.7500";"2.5958";"14.9758";"0.1255"
"156.0000";"2.6000";"15.0032";"0.1255"
"156.2500";"2.6042";"15.0295";"0.1258"
"156.5000";"2.6086";"15.0670";"0.1260"
"156.7500";"2.6127";"15.0983";"0.1267"
"157.0000";"2.6167";"15.1270";"0.1266"
"157.2500";"2.6207";"15.1508";"0.1269"
"157.5000";"2.6250";"15.1779";"0.1271"
"157.7500";"2.6294";"15.2128";"0.1272"
"158.0000";"2.6336";"15.2504";"0.1279"
"158.2500";"2.6376";"15.2795";"0.1279"
"158.5000";"2.6417";"15.3023";"0.1280"
"158.7500";"2.6458";"15.3298";"0.1287"
"159.0000";"2.6500";"15.3577";"0.1286"
"159.2500";"2.6543";"15.3965";"0.1288"
"159.5000";"2.6585";"15.4288";"0.1294"
"159.7500";"2.6626";"15.4594";"0.1294"
"160.0000";"2.6666";"15.4834";"0.1297"
"160.2500";"2.6708";"15.5116";"0.1300"
"160.5000";"2.6751";"15.5433";"0.1301"
"160.7500";"2.6793";"15.5821";"0.1306"
"161.0000";"2.6834";"15.6127";"0.1306"
"161.2500";"2.6874";"15.6363";"0.1310"
"161.5000";"2.6916";"15.6653";"0.1313"
"161.7500";"2.6960";"15.6981";"0.1318"
"162.0000";"2.7003";"15.7371";"0.1319"
"162.2500";"2.7043";"15.7660";"0.1322"
"162.5000";"2.7083";"15.7933";"0.1324"
"162.7500";"2.7123";"15.8166";"0.1326"
"163.0000";"2.7167";"15.8506";"0.1327"
"163.2500";"2.7210";"15.8847";"0.1333"
"163.5000";"2.7252";"15.9217";"0.1336"
"163.7500";"2.7292";"15.9483";"0.1338"
"164.0000";"2.7333";"15.9733";"0.1339"
"164.2500";"2.7375";"15.9985";"0.1342"
"164.5000";"2.7417";"16.0324";"0.1345"
"164.7500";"2.7460";"16.0719";"0.1348"
"165.0000";"2.7501";"16.1030";"0.1350"
"165.2500";"2.7542";"16.1295";"0.1355"
"165.5000";"2.7583";"16.1538";"0.1355"
"165.7500";"2.7626";"16.1882";"0.1357"
"166.0000";"2.7669";"16.2241";"0.1361"
"166.2500";"2.7710";"16.2581";"0.1364"
"166.5000";"2.7749";"16.2821";"0.1367"
"166.7500";"2.7790";"16.3094";"0.1368"
"167.0000";"2.7833";"16.3389";"0.1372"
"167.2500";"2.7878";"16.3796";"0.1374"
"167.5000";"2.7919";"16.4141";"0.1377"
"167.7500";"2.7959";"16.4416";"0.1379"
"168.0000";"2.7999";"16.4650";"0.1382"
"168.2500";"2.8041";"16.4933";"0.1383"
"168.5000";"2.8085";"16.5305";"0.1387"
"168.7500";"2.8127";"16.5689";"0.1390"
"169.0000";"2.8168";"16.6014";"0.1395"
"169.2500";"2.8208";"16.6254";"0.1396"
"169.5000";"2.8250";"16.6551";"0.1398"
"169.7500";"2.8293";"16.6854";"0.1399"
"170.0000";"2.8335";"16.7235";"0.1404"
"170.2500";"2.8376";"16.7556";"0.1406"
"170.5000";"2.8417";"16.7858";"0.1408"
"170.7500";"2.8458";"16.8119";"0.1413"
"171.0000";"2.8501";"16.8432";"0.1415"
"171.2500";"2.8544";"16.8807";"0.1417"
"171.5000";"2.8585";"16.9164";"0.1417"
"171.7500";"2.8626";"16.9452";"0.1421"
"172.0000";"2.8665";"16.9698";"0.1426"
"172.2500";"2.8708";"17.0010";"0.1427"
"172.5000";"2.8751";"17.0352";"0.1431"
"172.7500";"2.8794";"17.0766";"0.1433"
"173.0000";"2.8835";"17.1071";"0.1437"
"173.2500";"2.8875";"17.1340";"0.1437"
"173.5000";"2.8915";"17.1592";"0.1440"
"173.7500";"2.8959";"17.1923";"0.1447"
"174.0000";"2.9001";"17.2294";"0.1449"
"174.2500";"2.9043";"17.2666";"0.1449"
"174.5000";"2.9084";"17.2968";"0.1452"
"174.7500";"2.9125";"17.3237";"0.1455"
"175.0000";"2.9167";"17.3550";"0.1458"
"175.2500";"2.9210";"17.3894";"0.1463"
"175.5000";"2.9252";"17.4271";"0.1464"
"175.7500";"2.9292";"17.4559";"0.1469"
"176.0000";"2.9333";"17.4845";"0.1471"
"176.2500";"2.9374";"17.5127";"0.1472"
"176.5000";"2.9418";"17.5488";"0.1475"
"176.7500";"2.9461";"17.5861";"0.1479"
"177.0000";"2.9501";"17.6202";"0.1484"
"177.2500";"2.9541";"17.6446";"0.1483"
"177.5000";"2.9582";"17.6716";"0.1487"
"177.7500";"2.9625";"17.7040";"0.1488"
"178.0000";"2.9668";"17.7435";"0.1492"
"178.2500";"2.9711";"17.7824";"0.1496"
"178.5000";"2.9750";"17.8076";"0.1496"
"178.7500";"2.9791";"17.8350";"0.1498"
"179.0000";"2.9833";"17.8626";"0.1503"
"179.2500";"2.9877";"17.9012";"0.1504"
"179.5000";"2.9918";"17.9365";"0.1507"
"179.7500";"2.9958";"17.9696";"0.1511"
"180.0000";"2.9999";"17.9964";"0.1548"
"180.2500";"3.0042";"18.0263";"0.1540"
"180.5000";"3.0085";"18.0615";"0.1589"
"180.7500";"3.0127";"18.0994";"0.1670"
"181.0000";"3.0168";"18.1303";"0.1621"
"181.2500";"3.0208";"18.1559";"0.1664"
"181.5000";"3.0250";"18.1864";"0.1712"
"181.7500";"3.0291";"18.2168";"0.1733"
"182.0000";"3.0335";"18.2565";"0.1731"
"182.2500";"3.0377";"18.2933";"0.1656"
"182.5000";"3.0418";"18.3236";"0.1648"
"182.7500";"3.0457";"18.3484";"0.1649"
"183.0000";"3.0500";"18.3787";"0.1651"
"183.2500";"3.0542";"18.4122";"0.1629"
"183.5000";"3.0585";"18.4537";"0.1635"
"183.7500";"3.0626";"18.4872";"0.1648"
"184.0000";"3.0667";"18.5144";"0.1651"
"184.2500";"3.0708";"18.5431";"0.1656"
"184.5000";"3.0750";"18.5754";"0.1673"
"184.7500";"3.0794";"18.6132";"0.1675"
"185.0000";"3.0834";"18.6495";"0.1667"
"185.2500";"3.0875";"18.6790";"0.1663"
"185.5000";"3.0915";"18.7058";"0.1661"
"185.7500";"3.0959";"18.7397";"0.1667"
"186.0000";"3.1002";"18.7779";"0.1668"
"186.2500";"3.1044";"18.8154";"0.1671"
"186.5000";"3.1083";"18.8432";"0.1672"
"186.7500";"3.1124";"18.8706";"0.1676"
"187.0000";"3.1166";"18.9003";"0.1679"
"187.2500";"3.1210";"18.9367";"0.1680"
"187.5000";"3.1252";"18.9753";"0.1684"
"187.7500";"3.1293";"19.0102";"0.1687"
"188.0000";"3.1334";"19.0390";"0.1689"
"188.2500";"3.1374";"19.0655";"0.1691"
"188.5000";"3.1417";"19.0965";"0.1695"
"188.7500";"3.1460";"19.1366";"0.1699"
"189.0000";"3.1502";"19.1757";"0.1702"
"189.2500";"3.1542";"19.2044";"0.1705"
"189.5000";"3.1583";"19.2311";"0.1705"
"189.7500";"3.1625";"19.2625";"0.1708"
"190.0000";"3.1669";"19.3005";"0.1712"
"190.2500";"3.1710";"19.3369";"0.1712"
"190.5000";"3.1750";"19.3667";"0.1717"
"190.7500";"3.1791";"19.3941";"0.1720"
"191.0000";"3.1832";"19.4232";"0.1723"
"191.2500";"3.1876";"19.4623";"0.1727"
"191.5000";"3.1919";"19.5040";"0.1729"
"191.7500";"3.1960";"19.5359";"0.1732"
"192.0000";"3.2000";"19.5625";"0.1734"
"192.2500";"3.2041";"19.5921";"0.1739"
"192.5000";"3.2084";"19.6258";"0.1741"
"192.7500";"3.2127";"19.6659";"0.1746"
"193.0000";"3.2168";"19.7019";"0.1747"
"193.2500";"3.2209";"19.7337";"0.1751"
"193.5000";"3.2250";"19.7620";"0.1751"
"193.7500";"3.2292";"19.7931";"0.1753"
"194.0000";"3.2334";"19.8268";"0.1757"
"194.2500";"3.2376";"19.8686";"0.1762"
"194.5000";"3.2417";"19.9022";"0.1764"
"194.7500";"3.2458";"19.9305";"0.1767"
"195.0000";"3.2499";"19.9590";"0.1770"
"195.2500";"3.2543";"19.9971";"0.1774"
"195.5000";"3.2586";"20.0363";"0.1777"
"195.7500";"3.2627";"20.0712";"0.1781"
"196.0000";"3.2667";"20.1010";"0.1783"
"196.2500";"3.2707";"20.1263";"0.1784"
"196.5000";"3.2750";"20.1608";"0.1788"
"196.7500";"3.2794";"20.2012";"0.1790"
"197.0000";"3.2835";"20.2418";"0.1794"
"197.2500";"3.2875";"20.2700";"0.1796"
"197.5000";"3.2916";"20.2985";"0.1800"
"197.7500";"3.2957";"20.3272";"0.1803"
"198.0000";"3.3001";"20.3666";"0.1808"
"198.2500";"3.3043";"20.4049";"0.1810"
"198.5000";"3.3084";"20.4402";"0.1812"
"198.7500";"3.3125";"20.4709";"0.1815"
"199.0000";"3.3166";"20.5004";"0.1819"
"199.2500";"3.3210";"20.5350";"0.1821"
"199.5000";"3.3252";"20.5742";"0.1825"
"199.7500";"3.3293";"20.6106";"0.1826"
"200.0000";"3.3333";"20.6376";"0.1829"
"200.2500";"3.3374";"20.6674";"0.1833"
"200.5000";"3.3417";"20.7001";"0.1833"
"200.7500";"3.3461";"20.7430";"0.1840"
"201.0000";"3.3502";"20.7807";"0.1841"
"201.2500";"3.3542";"20.8119";"0.1845"
"201.5000";"3.3583";"20.8366";"0.1846"
"201.7500";"3.3624";"20.8678";"0.1848"
"202.0000";"3.3668";"20.9075";"0.1853"
"202.2500";"3.3711";"20.9502";"0.1858"
"202.5000";"3.3751";"20.9838";"0.1861"
"202.7500";"3.3791";"21.0098";"0.1862"
"203.0000";"3.3833";"21.0406";"0.1865"
"203.2500";"3.3876";"21.0729";"0.1868"
"203.5000";"3.3919";"21.1149";"0.1877"
"203.7500";"3.3959";"21.1484";"0.1879"
"204.0000";"3.4000";"21.1798";"0.1877"
"204.2500";"3.4041";"21.2080";"0.1887"
"204.5000";"3.4084";"21.2430";"0.1887"
"204.7500";"3.4127";"21.2817";"0.1890"
"205.0000";"3.4168";"21.3184";"0.1896"
"205.2500";"3.4209";"21.3495";"0.1901"
"205.5000";"3.4249";"21.3774";"0.1900"
"205.7500";"3.4291";"21.4102";"0.1906"
"206.0000";"3.4334";"21.4444";"0.1909"
"206.2500";"3.4377";"21.4897";"0.1913"
"206.5000";"3.4418";"21.5228";"0.1916"
"206.7500";"3.4458";"21.5512";"0.1919"
"207.0000";"3.4499";"21.5766";"0.1920"
"207.2500";"3.4542";"21.6125";"0.1924"
"207.5000";"3.4585";"21.6499";"0.1930"
"207.7500";"3.4627";"21.6898";"0.1930"
"208.0000";"3.4667";"21.7183";"0.1932"
"208.2500";"3.4707";"21.7429";"0.1935"
"208.5000";"3.4750";"21.7719";"0.1937"
"208.7500";"3.4794";"21.8090";"0.1943"
"209.0000";"3.4836";"21.8471";"0.1949"
"209.2500";"3.4875";"21.8706";"0.1952"
"209.5000";"3.4916";"21.8902";"0.1962"
"209.7500";"3.4957";"21.9074";"0.1972"
"210.0000";"3.5002";"21.9345";"0.1983"
"210.2500";"3.5044";"21.8429";"0.1958"
"210.5000";"3.5085";"21.5733";"0.1932"
"210.7500";"3.5125";"21.3087";"0.1901"
"211.0000";"3.5166";"21.1235";"0.1888"
"211.2500";"3.5208";"21.0076";"0.1877"
"211.5000";"3.5251";"20.9339";"0.1870"
"211.7500";"3.5293";"20.8828";"0.1857"
"212.0000";"3.5334";"20.8606";"0.1848"
"212.2500";"3.5375";"20.8448";"0.1840"
"212.5000";"3.5416";"20.8090";"0.1828"
"212.7500";"3.5460";"20.7670";"0.1834"
"213.0000";"3.5502";"20.7113";"0.1855"
"213.2500";"3.5542";"20.6706";"0.1883"
"213.5000";"3.5583";"20.6538";"0.1917"
"213.7500";"3.5625";"20.6603";"0.1952"
"214.0000";"3.5668";"20.6532";"0.1989"
"214.2500";"3.5711";"20.6464";"0.2024"
"214.5000";"3.5751";"20.6367";"0.2056"
"214.7500";"3.5791";"20.5848";"0.2093"
"215.0000";"3.5832";"20.5398";"0.2147"
"215.2500";"3.5875";"20.4894";"0.2221"
"215.5000";"3.5919";"20.4645";"0.2291"
"215.7500";"3.5960";"20.4576";"0.2351"
"216.0000";"3.6000";"20.4619";"0.2408"
"216.2500";"3.6040";"20.4383";"0.2471"
"216.5000";"3.6083";"20.4113";"0.2539"
"216.7500";"3.6126";"20.3808";"0.2609"
"217.0000";"3.6169";"20.3787";"0.2680"
"217.2500";"3.6209";"20.3785";"0.2749"
"217.5000";"3.6250";"20.3818";"0.2817"
"217.7500";"3.6292";"20.3859";"0.2886"
"218.0000";"3.6334";"20.3879";"0.2956"
"218.2500";"3.6377";"20.3991";"0.3024"
"218.5000";"3.6418";"20.4072";"0.3102"
"218.7500";"3.6459";"20.3952";"0.3180"
"219.0000";"3.6499";"20.3867";"0.3253"
"219.2500";"3.6542";"20.3927";"0.3330"
"219.5000";"3.6585";"20.4023";"0.3408"
"219.7500";"3.6628";"20.4143";"0.3489"
"220.0000";"3.6667";"20.4150";"0.3565"
"220.2500";"3.6708";"20.4209";"0.3639"
"220.5000";"3.6749";"20.4292";"0.3710"
"220.7500";"3.6793";"20.4452";"0.3783"
"221.0000";"3.6835";"20.4740";"0.3855"
"221.2500";"3.6876";"20.4943";"0.3927"
"221.5000";"3.6917";"20.5122";"0.3995"
"221.7500";"3.6958";"20.5221";"0.4073"
"222.0000";"3.7001";"20.5243";"0.4156"
"222.2500";"3.7043";"20.5068";"0.4249"
"222.5000";"3.7085";"20.4863";"0.4342"
"222.7500";"3.7124";"20.4650";"0.4428"
"223.0000";"3.7166";"20.4611";"0.4511"
"223.2500";"3.7209";"20.4768";"0.4588"
"223.5000";"3.7252";"20.5031";"0.4668"
"223.7500";"3.7293";"20.5180";"0.4750"
"224.0000";"3.7334";"20.5249";"0.4830"
"224.2500";"3.7374";"20.4927";"0.4922"
"224.5000";"3.7416";"20.4725";"0.5013"
"224.7500";"3.7459";"20.4624";"0.5107"
"225.0000";"3.7502";"20.4727";"0.5195"
"225.2500";"3.7543";"20.4838";"0.5281"
"225.5000";"3.7583";"20.4835";"0.5364"
"225.7500";"3.7624";"20.4918";"0.5442"
"226.0000";"3.7667";"20.4998";"0.5525"
"226.2500";"3.7710";"20.5183";"0.5608"
"226.5000";"3.7752";"20.5288";"0.5686"
"226.7500";"3.7792";"20.5220";"0.5769"
"227.0000";"3.7833";"20.5143";"0.5854"
"227.2500";"3.7876";"20.5058";"0.5947"
"227.5000";"3.7918";"20.5018";"0.6034"
"227.7500";"3.7960";"20.4987";"0.6124"
"228.0000";"3.8001";"20.4872";"0.6213"
"228.2500";"3.8041";"20.4657";"0.6304"
"228.5000";"3.8083";"20.4500";"0.6397"
"228.7500";"3.8126";"20.4436";"0.6487"
"229.0000";"3.8169";"20.4407";"0.6579"
"229.2500";"3.8210";"20.4256";"0.6669"
"229.5000";"3.8250";"20.3934";"0.6762"
"229.7500";"3.8290";"20.3518";"0.6855"
"230.0000";"3.8333";"20.3370";"0.6941"
"230.2500";"3.8377";"20.3253";"0.7031"
"230.5000";"3.8419";"20.3118";"0.7124"
"230.7500";"3.8459";"20.2919";"0.7211"
"231.0000";"3.8499";"20.2800";"0.7295"
"231.2500";"3.8541";"20.2752";"0.7376"
"231.5000";"3.8584";"20.2804";"0.7458"
"231.7500";"3.8627";"20.2842";"0.7541"
"232.0000";"3.8667";"20.2576";"0.7634"
"232.2500";"3.8708";"20.2207";"0.7727"
"232.5000";"3.8749";"20.2005";"0.7814"
"232.7500";"3.8793";"20.2064";"0.7893"
"233.0000";"3.8836";"20.2283";"0.7968"
"233.2500";"3.8876";"20.2551";"0.8040"
"233.5000";"3.8916";"20.2702";"0.8109"
"233.7500";"3.8958";"20.2831";"0.8179"
"234.0000";"3.9000";"20.3040";"0.8252"
"234.2500";"3.9044";"20.3332";"0.8324"
"234.5000";"3.9086";"20.3559";"0.8397"
"234.7500";"3.9126";"20.3676";"0.8473"
"235.0000";"3.9166";"20.3817";"0.8546"
"235.2500";"3.9207";"20.4018";"0.8618"
"235.5000";"3.9251";"20.4150";"0.8698"
"235.7500";"3.9293";"20.4096";"0.8786"
"236.0000";"3.9335";"20.4203";"0.8865"
"236.2500";"3.9375";"20.4332";"0.8939"
"236.5000";"3.9416";"20.4460";"0.9015"
"236.7500";"3.9459";"20.4616";"0.9088"
"237.0000";"3.9502";"20.4925";"0.9160"
"237.2500";"3.9543";"20.5201";"0.9236"
"237.5000";"3.9583";"20.5324";"0.9315"
"237.7500";"3.9624";"20.5508";"0.9393"
"238.0000";"3.9667";"20.5680";"0.9470"
"238.2500";"3.9711";"20.5598";"0.9558"
"238.5000";"3.9752";"20.5478";"0.9647"
"238.7500";"3.9792";"20.5272";"0.9736"
"239.0000";"3.9832";"20.5076";"0.9829"
"239.2500";"3.9875";"20.5144";"0.9912"
"239.5000";"3.9918";"20.5318";"0.9994"
"239.7500";"3.9961";"20.5372";"1.0077"
"240.0000";"4.0001";"20.5449";"1.0158"
"240.2500";"4.0042";"20.5488";"1.0238"
"240.5000";"4.0082";"20.5454";"1.0318"
"240.7500";"4.0125";"20.5504";"1.0400"
"241.0000";"4.0168";"20.5481";"1.0480"
"241.2500";"4.0209";"20.5231";"1.0571"
"241.5000";"4.0251";"20.4669";"1.0673"
"241.7500";"4.0291";"20.4242";"1.0768"
"242.0000";"4.0333";"20.3990";"1.0856"
"242.2500";"4.0377";"20.3760";"1.0945"
"242.4440";"4.0407";"20.3374";"1.1000"
"242.6940";"4.0413";"20.1979";"1.1000"
"242.9440";"4.0412";"20.0629";"1.1000"
"243.1940";"4.0409";"19.9718";"1.1000"
"243.4440";"4.0407";"19.9012";"1.1000"
"243.6940";"4.0405";"19.8430";"1.1000"
"243.9440";"4.0404";"19.7966";"1.1000"
"244.1940";"4.0404";"19.7586";"1.1000"
"244.4440";"4.0404";"19.7267";"1.1000"
"244.6940";"4.0404";"19.6983";"1.1000"
"244.9440";"4.0404";"19.6737";"1.1000"
"245.1940";"4.0404";"19.6518";"1.1000"
"245.4440";"4.0404";"19.6338";"1.1000"
"245.6940";"4.0404";"19.6178";"1.1000"
"245.9440";"4.0404";"19.6035";"1.1000"
"246.1940";"4.0404";"19.5904";"1.1000"
"246.4440";"4.0404";"19.5788";"1.1000"
"246.6940";"4.0404";"19.5686";"1.1000"
"246.9440";"4.0404";"19.5591";"1.1000"
"247.1940";"4.0404";"19.5510";"1.1000"
"247.4440";"4.0404";"19.5424";"1.1000"
"247.6940";"4.0404";"19.5348";"1.1000"
"247.9440";"4.0404";"19.5280";"1.1000"
"248.1940";"4.0404";"19.5204";"1.1000"
"248.4440";"4.0404";"19.5151";"1.1000"
"248.6940";"4.0404";"19.5094";"1.1000"
"248.9440";"4.0404";"19.5035";"1.1000"
"249.1940";"4.0404";"19.4992";"1.1000"
"249.4440";"4.0404";"19.4940";"1.1000"
"249.6940";"4.0404";"19.4884";"1.1000"
"249.9440";"4.0404";"19.4842";"1.1000"
"250.1940";"4.0404";"19.4797";"1.1000"
"250.4440";"4.0404";"19.4748";"1.1000"
"250.6940";"4.0404";"19.4715";"1.1000"
"250.9440";"4.0404";"19.4674";"1.1000"
"251.1940";"4.0404";"19.4632";"1.1000"
"251.4440";"4.0404";"19.4601";"1.1000"
"251.6940";"4.0404";"19.4567";"1.1000"
"251.9440";"4.0404";"19.4526";"1.1000"
"252.1940";"4.0404";"19.4499";"1.1000"
"252.4440";"4.0403";"19.4474";"1.1000"
"252.6940";"4.0403";"19.4431";"1.1000"
"252.9440";"4.0403";"19.4405";"1.1000"
"253.1940";"4.0403";"19.4376";"1.1000"
"253.4440";"4.0403";"19.4336";"1.1000"
"253.6940";"4.0403";"19.4317";"1.1000"
"253.9440";"4.0403";"19.4290";"1.1000"
"254.1940";"4.0403";"19.4257";"1.1000"
"254.4440";"4.0403";"19.4233";"1.1000"
"254.6940";"4.0403";"19.4210";"1.1000"
"254.9440";"4.0403";"19.4179";"1.1000"
"255.1940";"4.0404";"19.4167";"1.1000"
"255.4440";"4.0404";"19.4141";"1.1000"
"255.6940";"4.0404";"19.4112";"1.1000"
"255.9440";"4.0404";"19.4094";"1.1000"
"256.1940";"4.0404";"19.4079";"1.1000"
"256.4440";"4.0404";"19.4054";"1.1000"
"256.6940";"4.0404";"19.4041";"1.1000"
"256.9440";"4.0404";"19.4020";"1.1000"
"257.1940";"4.0404";"19.3992";"1.1000"
"257.4440";"4.0404";"19.3980";"1.1000"
"257.6940";"4.0404";"19.3957";"1.1000"
"257.9440";"4.0404";"19.3931";"1.1000"
"258.1940";"4.0404";"19.3914";"1.1000"
"258.4440";"4.0404";"19.3890";"1.1000"
"258.6940";"4.0404";"19.3868";"1.1000"
"258.9440";"4.0404";"19.3858";"1.1000"
"259.1940";"4.0404";"19.3835";"1.1000"
"259.4440";"4.0404";"19.3815";"1.1000"
"259.6260";"4.0404";"19.3804";"1.1000"
"259.8760";"4.1011";"21.1114";"1.1000"
"260.1260";"4.1925";"21.8206";"1.1000"
"260.3760";"4.2758";"21.5532";"1.1000"
"260.6260";"4.3591";"21.6703";"1.1000"
"260.8760";"4.4424";"21.8361";"1.1000"
"261.1260";"4.5258";"21.6816";"1.1000"
"261.3760";"4.6090";"22.2446";"1.1000"
"261.6260";"4.6923";"22.8638";"1.1000"
"261.8760";"4.7757";"23.2735";"1.1000"
"262.1260";"4.8591";"23.6164";"1.1000"
"262.3760";"4.9424";"23.9092";"1.1000"
"262.6260";"5.0256";"24.1791";"1.1000"
"262.8760";"5.1090";"24.4423";"1.1000"
"263.1260";"5.1923";"24.7003";"1.1000"
"263.3760";"5.2757";"24.9590";"1.1000"
"263.6260";"5.3590";"25.2169";"1.1000"
"263.8760";"5.4425";"25.4713";"1.1000"
"264.1260";"5.5257";"25.7208";"1.1000"
"264.3760";"5.6091";"25.9726";"1.1000"
"264.6260";"5.6924";"26.2159";"1.1000"
"264.8760";"5.7756";"26.4562";"1.1000"
"265.1260";"5.8591";"26.6987";"1.1000"
"265.3760";"5.9424";"26.9317";"1.1000"
"265.6260";"6.0257";"27.1598";"1.1000"
"265.8760";"6.1091";"27.3860";"1.1000"
"266.1260";"6.1923";"27.6032";"1.1000"
"266.3760";"6.2757";"27.8202";"1.1000"
"266.6260";"6.3591";"28.0352";"1.1000"
"266.8760";"6.4425";"28.2443";"1.1000"
"267.1260";"6.5257";"28.4452";"1.1000"
"267.3760";"6.6089";"28.6438";"1.1000"
"267.6260";"6.6922";"28.8369";"1.1000"
"267.8760";"6.7758";"29.0288";"1.1000"
"268.1260";"6.8590";"29.2164";"1.1000"
"268.3760";"6.9425";"29.3962";"1.1000"
"268.6260";"7.0257";"29.5699";"1.1000"
"268.8760";"7.1091";"29.7382";"1.1000"
"269.1260";"7.1923";"29.9055";"1.1000"
"269.3760";"7.2757";"30.0683";"1.1000"
"269.6260";"7.3590";"30.2264";"1.1000"
"269.8760";"7.4424";"30.3795";"1.1000"
"270.1260";"7.5257";"30.5265";"1.1000"
"270.3760";"7.6091";"30.6732";"1.1000"
"270.6260";"7.6924";"30.8112";"1.1000"
"270.8760";"7.7757";"30.9480";"1.1000"
"271.1260";"7.8590";"31.0828";"1.1000"
"271.3760";"7.9424";"31.2104";"1.1000"
"271.6260";"8.0257";"31.3365";"1.1000"
"271.8760";"8.1091";"31.4606";"1.1000"
"272.1260";"8.1922";"31.5773";"1.1000"
"272.3760";"8.2757";"31.6954";"1.1000"
"272.6260";"8.3591";"31.8129";"1.1000"
"272.8760";"8.4425";"31.9218";"1.1000"
"273.1260";"8.5257";"32.0299";"1.1000"
"273.3760";"8.6090";"32.1349";"1.1000"
"273.6260";"8.6923";"32.2337";"1.1000"
"273.8760";"8.7757";"32.3378";"1.1000"
"274.1260";"8.8591";"32.4365";"1.1000"
"274.3760";"8.9425";"32.5300";"1.1000"
"274.6260";"9.0257";"32.6201";"1.1000"
"274.8760";"9.1090";"32.7084";"1.1000"
"275.1260";"9.1924";"32.7941";"1.1000"
"275.3760";"9.2757";"32.8787";"1.1000"
"275.6260";"9.3590";"32.9639";"1.1000"
"275.8760";"9.4424";"33.0397";"1.1000"
"276.1260";"9.5258";"33.1137";"1.1000"
"276.3760";"9.6091";"33.1905";"1.1000"
"276.6260";"9.6924";"33.2597";"1.1000"
"276.8760";"9.7756";"33.3307";"1.1000"
"277.1260";"9.8590";"33.4010";"1.1000"
"277.3760";"9.9425";"33.4643";"1.1000"
"277.6260";"10.0257";"33.5276";"1.1000"
"277.8760";"10.1091";"33.5890";"1.1000"
"278.1260";"10.1923";"33.6462";"1.1000"
"278.3760";"10.2757";"33.7057";"1.1000"
"278.6260";"10.3591";"33.7647";"1.1000"
"278.8760";"10.4424";"33.8170";"1.1000"
"279.1260";"10.5258";"33.8687";"1.1000"
"279.3760";"10.6090";"33.9172";"1.1000"
"279.6260";"10.6923";"33.9651";"1.1000"
"279.8760";"10.7757";"34.0171";"1.1000"
"280.1260";"10.8591";"34.0613";"1.1000"
"280.3760";"10.9424";"34.1057";"1.1000"
"280.6260";"11.0257";"34.1455";"1.1000"
"280.8760";"11.1089";"34.1843";"1.1000"
"281.1260";"11.1924";"34.2257";"1.1000"
"281.3760";"11.2758";"34.2640";"1.1000"
"281.6260";"11.3590";"34.2992";"1.1000"
"281.8760";"11.4424";"34.3342";"1.1000"
"282.1260";"11.5258";"34.3665";"1.1000"
"282.3760";"11.6091";"34.3987";"1.1000"
"282.6260";"11.6924";"34.4302";"1.1000"
"282.8760";"11.7756";"34.4603";"1.1000"
"283.1260";"11.8590";"34.4910";"1.1000"
"283.3760";"11.9425";"34.5176";"1.1000"
"283.6260";"12.0258";"34.5425";"1.1000"
"283.8760";"12.1091";"34.5665";"1.1000"
"284.1260";"12.1922";"34.5885";"1.1000"
"284.3760";"12.2756";"34.6139";"1.1000"
"284.6260";"12.3592";"34.6379";"1.1000"
"284.8760";"12.4424";"34.6541";"1.1000"
"285.1260";"12.5256";"34.6749";"1.1000"
"285.3760";"12.6091";"34.6932";"1.1000"
"285.6260";"12.6923";"34.7081";"1.1000"
"285.8760";"12.7757";"34.7276";"1.1000"
"286.1260";"12.8592";"34.7449";"1.1000"
"286.3760";"12.9425";"34.7557";"1.1000"
"286.6260";"13.0257";"34.7686";"1.1000"
"286.8760";"13.1090";"34.7804";"1.1000"
"287.1260";"13.1923";"34.7926";"1.1000"
"287.3760";"13.2757";"34.8034";"1.1000"
"287.6260";"13.3591";"34.8153";"1.1000"
"287.8760";"13.4424";"34.8210";"1.1000"
"288.1260";"13.5257";"34.8293";"1.1000"
"288.3760";"13.6092";"34.8382";"1.1000"
"288.6260";"13.6924";"34.8412";"1.1000"
"288.8760";"13.7756";"34.8469";"1.1000"
"289.1260";"13.8591";"34.8540";"1.1000"
"289.3760";"13.9425";"34.8550";"1.1000"
"289.6260";"14.0258";"34.8570";"1.1000"
"289.8760";"14.1090";"34.8604";"1.1000"
"290.1260";"14.1923";"34.8592";"1.1000"
"290.3760";"14.2757";"34.8608";"1.1000"
"290.6260";"14.3591";"34.8604";"1.1000"
"290.8760";"14.4425";"34.8572";"1.1000"
"291.1260";"14.5257";"34.8548";"1.1000"
"291.3760";"14.6091";"34.8507";"1.1000"
"291.6260";"14.6923";"34.8442";"1.1000"
"291.8760";"14.7758";"34.8421";"1.1000"
"292.1260";"14.8590";"34.8351";"1.1000"
"292.3760";"14.9425";"34.8283";"1.1000"
"292.6260";"15.0258";"34.8167";"1.1000"
"292.8760";"15.1090";"34.8049";"1.1000"
"293.1260";"15.1923";"34.7956";"1.1000"
"293.3760";"15.2758";"34.7826";"1.1000"
"293.6260";"15.3591";"34.7693";"1.1000"
"293.8760";"15.4424";"34.7541";"1.1000"
"294.1260";"15.5257";"34.7345";"1.1000"
"294.3760";"15.6091";"34.7168";"1.1000"
"294.6260";"15.6924";"34.6960";"1.1000"
"294.8760";"15.7756";"34.6728";"1.1000"
"295.1260";"15.8591";"34.6503";"1.1000"
"295.3760";"15.9425";"34.6205";"1.1000"
"295.6260";"16.0258";"34.5903";"1.1000"
"295.8760";"16.1091";"34.5571";"1.1000"
"296.1260";"16.1922";"34.5182";"1.1000"
"296.3760";"16.2757";"34.4803";"1.1000"
"296.6260";"16.3591";"34.4390";"1.1000"
"296.8760";"16.4425";"34.3873";"1.1000"
"297.1260";"16.5257";"34.3358";"1.1000"
"297.3760";"16.6090";"34.2727";"1.1000"
"297.6260";"16.6923";"34.2045";"1.1000"
"297.8760";"16.7758";"34.1369";"1.1000"
"298.1260";"16.8591";"34.0581";"1.1000"
"298.3760";"16.9424";"33.9691";"1.1000"
"298.6260";"17.0257";"33.8734";"1.1000"
"298.8760";"17.1091";"33.7691";"1.1000"
"299.1260";"17.1923";"33.6609";"1.1000"
"299.3760";"17.2758";"33.5462";"1.1000"
"299.6260";"17.3592";"33.4210";"1.1000"
"299.8760";"17.4424";"33.2849";"1.1000"
"300.1260";"17.5258";"33.1416";"1.1000"
"300.3760";"17.6091";"32.9931";"1.1000"
"300.6260";"17.6924";"32.8339";"1.1000"
"300.8760";"17.7757";"32.6667";"1.1000"
"301.1260";"17.8589";"32.4919";"1.1000"
"301.3760";"17.9425";"32.3042";"1.1000"
"301.6260";"18.0258";"32.1071";"1.1000"
"301.8760";"18.1091";"31.9025";"1.1000"
"302.1260";"18.1923";"31.6857";"1.1000"
"302.3760";"18.2757";"31.4572";"1.1000"
"302.6260";"18.3591";"31.2200";"1.1000"
"302.8760";"18.4426";"30.9609";"1.1000"
"303.1260";"18.5258";"30.6908";"1.1000"
"303.3760";"18.6090";"30.4052";"1.1000"
"303.6260";"18.6924";"30.1011";"1.1000"
"303.8760";"18.7758";"29.7784";"1.1000"
"304.1260";"18.8591";"29.4253";"1.1000"
"304.3760";"18.9425";"29.0297";"1.1000"
"304.5740";"19.0092";"15.9545";"1.1000"